Workbook

Sheet 📋 HOW TO USE
A1: 🎨 PAINT PACKAGING BENCHMARKING — MASTER DATA COLLECTION SYSTEM
A2: PROJECT: Product Packaging Revision & Relaunch | Brands: Asian Paints | Birla Opus | Dulux Paints | JSW Paints
A4: 📌 WHAT IS THIS FILE?
B5: This file is your complete, single-shot data collection system for Paint Packaging Benchmarking.
B6: ONE ROW = ONE OBSERVER. Each person fills in their scores ONCE. All analysis updates automatically.
B7: Sheets: (1) HOW TO USE (2) 📝 DATA ENTRY — the only sheet observers fill (3-7) Analysis sheets — auto-calculated, do not edit manually.
A9: 📂 SHEET GUIDE
B10: 📝 DATA ENTRY → The only sheet you/observers fill. One row per observer. Dropdowns throughout.
B11: 📊 PEEF Analysis → Auto-calculates Packaging Effectiveness Score per brand (Visibility, Premium, SKU, Communication).
B12: 🏆 Benchmarking → Auto-scores all 5 pillars of the Benchmarking Framework (25 parameters × 4 brands).
B13: 📈 Brand Ranking → Aggregates ranking scores (Rank 1=5pts, Rank 2=3pts, Rank 3=1pt) per brand per dimension.
B14: 🔢 Coding Matrix → Converts brand-mention frequency into scores /10 using Method 1 formula.
B15: 🎯 Master Summary → Final PES, PEI, Ranking Score, Mention Score → ONE combined index per brand. Ready for PPT.
A17: ✍️ HOW TO COLLECT DATA (Step by Step)
B18: STEP 1 — Go to 📝 DATA ENTRY sheet. Each observer fills one row from left to right.
B19: STEP 2 — Fill profile columns: Name, Date, Location, Stakeholder Type (dropdown), Experience.
B20: STEP 3 — Score columns B1–B25 (PEEF scores): Rate each brand on each parameter using 1–10 scale. Use dropdowns.
B21: STEP 4 — Fill ranking columns: Rank Top 3 brands for each dimension (e.g., Q_VIS_R1 = brand ranked 1st for Visibility).
B22: STEP 5 — Fill brand mention columns: Which brand did you mention most for each theme? Select from dropdown.
B23: STEP 6 — After all observers are done, check 🎯 Master Summary for final brand scores.
B24: NOTE — You can have 100+ observers in the same sheet. Just add rows. All formulas auto-expand via AVERAGEIF.
A26: 📏 SCORING SCALE (Use consistently across all score columns)
B27: 10 = Best in Market (World-class, sets the benchmark)
B28: 9 = Excellent (Clearly superior)
B29: 8 = Very Good (Strong performance, minor gaps)
B30: 7 = Good (Above average, noticeable strengths)
B31: 6 = Slightly Above Average
B32: 5 = Average (Neither strong nor weak)
B33: 4 = Slightly Below Average
B34: 3 = Below Average / Confusing
B35: 2 = Poor
B36: 1 = Very Poor / Fails completely
A38: 👥 WHO FILLS WHAT (Stakeholder Guide)
B39: Dealer/Retailer → PEEF: Visibility + SKU Clarity + Communication | Benchmarking: Retail & Trade pillar
B40: Contractor/Painter→ PEEF: SKU Clarity + Visibility | Benchmarking: Retail & Trade, SKU Architecture
B41: End Consumer → PEEF: Premium Feel + Communication | Benchmarking: Visual Identity, Premium Perception
B42: Architect/Designer→ PEEF: Premium Feel | Benchmarking: Premium Perception, Visual Identity
B43: Distributor/Whol. → PEEF: SKU Clarity | Benchmarking: SKU Architecture
B44: Researcher (You) → ALL columns — do a full shelf audit for each brand
B45: TIP: If a stakeholder type doesn't evaluate a dimension, they can leave those cells blank. Formulas handle blanks.

Sheet 📝 DATA ENTRY
A1: 📝 PAINT PACKAGING BENCHMARKING — MASTER DATA ENTRY SHEET | ONE ROW = ONE OBSERVER | Fill dropdowns throughout
A2: SCALE: 1=Very Poor | 3=Poor | 5=Average | 7=Good | 8=Very Good | 9=Excellent | 10=Best in Market | BRANDS: AP=Asian Paints | BO=Birla Opus | DP=Dulux Paints | JSW=JSW Paints
A3: OBSERVER PROFILE | G3: PEEF DIM 1: VISIBILITY (Score each brand 1-10) | W3: PEEF DIM 2: PREMIUM FEEL (Score each brand 1-10) | AM3: PEEF DIM 3: SKU CLARITY (Score each brand 1-10) | BC3: PEEF DIM 4: COMMUNICATION EFFECTIVENESS (Score each brand 1-10) | BS3: BENCHMARKING PILLAR 1: VISUAL IDENTITY (1-10) | CM3: BENCHMARKING PILLAR 2: COMMUNICATION (1-10) | DG3: BENCHMARKING PILLAR 3: SKU ARCHITECTURE (1-10) | EA3: BENCHMARKING PILLAR 4: RETAIL & TRADE (1-10) | EU3: BENCHMARKING PILLAR 5: PREMIUM PERCEPTION (1-10) | FO3: BRAND RANKINGS — Rank Top 3 Brands per Dimension (select from dropdown) | GD3: BRAND MENTION CODING — Which brand comes to mind FIRST? (select from dropdown)
A4: Fill for every observer | G4: Brand Visibility (Logo Prominence) | K4: Shelf Impact (Stand-out on shelf) | O4: Color Contrast (Visual differentiation) | S4: Distance Recognition (5–10 feet) | W4: Luxury Appeal (Aspirational look) | AA4: Design Sophistication (Modernity) | AE4: Premium Cues (Metallics, gradients, typo) | AI4: Trust Perception (Reliability signals) | AM4: Variant Differentiation (SKU to SKU) | AQ4: Segment Differentiation (Economy/Premium/Luxury) | AU4: Color Coding Logic (Visual navigation ease) | AY4: Naming Structure (Product name clarity) | BC4: Product Type Clarity (Interior/Exterior/Primer) | BG4: Benefit Communication (Claims visibility) | BK4: Information Hierarchy (Logical flow) | BO4: Readability (Ease of understanding text) | BS4: Brand Visibility (Logo prominence) | BW4: Design Modernity | CA4: Typography Readability | CE4: Color Consistency with brand | CI4: Visual Appeal (Overall attractiveness) | CM4: Product Category Clarity (Int/Ext/Primer) | CQ4: Benefit Visibility (Claims on pack) | CU4: Finish Communication (Matte/Gloss/Satin) | CY4: Information Hierarchy | DC4: Readability of communication | DG4: Variant Differentiation | DK4: Segment Differentiation (Luxury/Economy) | DO4: Colour Coding Logic | DS4: Naming Structure | DW4: Portfolio Consistency | EA4: Shelf Visibility | EE4: Distance Recognition | EI4: Dealer Recommendation Ease | EM4: Contractor Recognition | EQ4: Product Retrieval Speed | EU4: Luxury Appeal | EY4: Trust Perception | FC4: Emotional Appeal | FG4: Material/Pack Quality Perception | FK4: Modern Appearance | FO4: Shelf Visibility — Which brand stands out most? | FR4: Premium Feel — Which brand looks most premium? | FU4: SKU Clarity — Which brand is easiest to navigate? | FX4: Communication — Which brand communicates best? | GA4: Overall — Which brand has the best packaging overall? | GD4: Fastest Moving / Most Recommended by you | GE4: First Noticed on Shelf (instinctive) | GF4: Looks Most Premium | GG4: Creates Highest Trust | GH4: Easiest to Understand | GI4: Most Confusing Packaging | GJ4: Looks Most Modern | GK4: Would You Personally Recommend / Buy
A5: Obs. ID | B5: Observer Name | C5: Interview Date | D5: City / Location | E5: Stakeholder Type | F5: Exp. (Years) | G5: AP BV (30%) | H5: BO BV (30%) | I5: DP BV (30%) | J5: JSW BV (30%) | K5: AP SI (30%) | L5: BO SI (30%) | M5: DP SI (30%) | N5: JSW SI (30%) | O5: AP CC (20%) | P5: BO CC (20%) | Q5: DP CC (20%) | R5: JSW CC (20%) | S5: AP DR (20%) | T5: BO DR (20%) | U5: DP DR (20%) | V5: JSW DR (20%) | W5: AP LA (25%) | X5: BO LA (25%) | Y5: DP LA (25%) | Z5: JSW LA (25%) | AA5: AP DS (25%) | AB5: BO DS (25%) | AC5: DP DS (25%) | AD5: JSW DS (25%) | AE5: AP PC (25%) | AF5: BO PC (25%) | AG5: DP PC (25%) | AH5: JSW PC (25%) | AI5: AP TP (25%) | AJ5: BO TP (25%) | AK5: DP TP (25%) | AL5: JSW TP (25%) | AM5: AP VD (30%) | AN5: BO VD (30%) | AO5: DP VD (30%) | AP5: JSW VD (30%) | AQ5: AP SD (25%) | AR5: BO SD (25%) | AS5: DP SD (25%) | AT5: JSW SD (25%) | AU5: AP CL (25%) | AV5: BO CL (25%) | AW5: DP CL (25%) | AX5: JSW CL (25%) | AY5: AP NS (20%) | AZ5: BO NS (20%) | BA5: DP NS (20%) | BB5: JSW NS (20%) | BC5: AP PT (25%) | BD5: BO PT (25%) | BE5: DP PT (25%) | BF5: JSW PT (25%) | BG5: AP BC (25%) | BH5: BO BC (25%) | BI5: DP BC (25%) | BJ5: JSW BC (25%) | BK5: AP IH (25%) | BL5: BO IH (25%) | BM5: DP IH (25%) | BN5: JSW IH (25%) | BO5: AP RD (25%) | BP5: BO RD (25%) | BQ5: DP RD (25%) | BR5: JSW RD (25%) | BS5: AP BViz | BT5: BO BViz | BU5: DP BViz | BV5: JSW BViz | BW5: AP DM | BX5: BO DM | BY5: DP DM | BZ5: JSW DM | CA5: AP TR | CB5: BO TR | CC5: DP TR | CD5: JSW TR | CE5: AP ColC | CF5: BO ColC | CG5: DP ColC | CH5: JSW ColC | CI5: AP VA | CJ5: BO VA | CK5: DP VA | CL5: JSW VA | CM5: AP PCC | CN5: BO PCC | CO5: DP PCC | CP5: JSW PCC | CQ5: AP BenV | CR5: BO BenV | CS5: DP BenV | CT5: JSW BenV | CU5: AP FC | CV5: BO FC | CW5: DP FC | CX5: JSW FC | CY5: AP InfoH | CZ5: BO InfoH | DA5: DP InfoH | DB5: JSW InfoH | DC5: AP Read | DD5: BO Read | DE5: DP Read | DF5: JSW Read | DG5: AP VarD | DH5: BO VarD | DI5: DP VarD | DJ5: JSW VarD | DK5: AP SegD | DL5: BO SegD | DM5: DP SegD | DN5: JSW SegD | DO5: AP CCL | DP5: BO CCL | DQ5: DP CCL | DR5: JSW CCL | DS5: AP NamS | DT5: BO NamS | DU5: DP NamS | DV5: JSW NamS | DW5: AP PortC | DX5: BO PortC | DY5: DP PortC | DZ5: JSW PortC | EA5: AP ShV | EB5: BO ShV | EC5: DP ShV | ED5: JSW ShV | EE5: AP DistR | EF5: BO DistR | EG5: DP DistR | EH5: JSW DistR | EI5: AP DRE | EJ5: BO DRE | EK5: DP DRE | EL5: JSW DRE | EM5: AP ConR | EN5: BO ConR | EO5: DP ConR | EP5: JSW ConR | EQ5: AP PRS | ER5: BO PRS | ES5: DP PRS | ET5: JSW PRS | EU5: AP LuxA | EV5: BO LuxA | EW5: DP LuxA | EX5: JSW LuxA | EY5: AP TrustP | EZ5: BO TrustP | FA5: DP TrustP | FB5: JSW TrustP | FC5: AP EmoA | FD5: BO EmoA | FE5: DP EmoA | FF5: JSW EmoA | FG5: AP MatP | FH5: BO MatP | FI5: DP MatP | FJ5: JSW MatP | FK5: AP ModA | FL5: BO ModA | FM5: DP ModA | FN5: JSW ModA | FO5: 🥇 Rank 1 | FP5: 🥈 Rank 2 | FQ5: 🥉 Rank 3 | FR5: 🥇 Rank 1 | FS5: 🥈 Rank 2 | FT5: 🥉 Rank 3 | FU5: 🥇 Rank 1 | FV5: 🥈 Rank 2 | FW5: 🥉 Rank 3 | FX5: 🥇 Rank 1 | FY5: 🥈 Rank 2 | FZ5: 🥉 Rank 3 | GA5: 🥇 Rank 1 | GB5: 🥈 Rank 2 | GC5: 🥉 Rank 3 | GD5: Brand Mentioned (MFast) | GE5: Brand Mentioned (MFirst) | GF5: Brand Mentioned (MPrem) | GG5: Brand Mentioned (MTrust) | GH5: Brand Mentioned (MEasy) | GI5: Brand Mentioned (MConf) | GJ5: Brand Mentioned (MModern) | GK5: Brand Mentioned (MWould)
A6: =IF(B6<>"","OBS-"&TEXT(ROW()-5,"000"),"") | BS6: 10
A7: =IF(B7<>"","OBS-"&TEXT(ROW()-5,"000"),"") | BS7: 7
A8: =IF(B8<>"","OBS-"&TEXT(ROW()-5,"000"),"")
A9: =IF(B9<>"","OBS-"&TEXT(ROW()-5,"000"),"")
A10: =IF(B10<>"","OBS-"&TEXT(ROW()-5,"000"),"")
A11: =IF(B11<>"","OBS-"&TEXT(ROW()-5,"000"),"")
A12: =IF(B12<>"","OBS-"&TEXT(ROW()-5,"000"),"")
A13: =IF(B13<>"","OBS-"&TEXT(ROW()-5,"000"),"")
A14: =IF(B14<>"","OBS-"&TEXT(ROW()-5,"000"),"")
A15: =IF(B15<>"","OBS-"&TEXT(ROW()-5,"000"),"")
A16: =IF(B16<>"","OBS-"&TEXT(ROW()-5,"000"),"")
A17: =IF(B17<>"","OBS-"&TEXT(ROW()-5,"000"),"")
A18: =IF(B18<>"","OBS-"&TEXT(ROW()-5,"000"),"")
A19: =IF(B19<>"","OBS-"&TEXT(ROW()-5,"000"),"")
... A205: =IF(B205<>"","OBS-"&TEXT(ROW()-5,"000"),"")

Sheet 📊 PEEF Analysis
A1: 📊 PACKAGING EFFECTIVENESS EVALUATION FRAMEWORK (PEEF) — Auto-Calculated from Data Entry
A2: Formula: PES = (Visibility×25%) + (Premium Feel×25%) + (SKU Clarity×25%) + (Communication×25%) | Scale: 0–10 | Scores auto-pulled from DATA ENTRY sheet
A3: PEEF Dimension / Parameter | C3: Weight | D3: Asian Paints | E3: Birla Opus | F3: Dulux Paints | G3: JSW Paints
A4: 🔵 DIMENSION 1: VISIBILITY
A5: ▸ Brand Visibility (Logo Prominence) | B5: BV | C5: 30% | D5: =IFERROR(ROUND(AVERAGEIF('📝 DATA ENTRY'!G6:G205,">0"),1),"") | E5: =IFERROR(ROUND(AVERAGEIF('📝 DATA ENTRY'!H6:H205,">0"),1),"") | F5: =IFERROR(ROUND(AVERAGEIF('📝 DATA ENTRY'!I6:I205,">0"),1),"") | G5: =IFERROR(ROUND(AVERAGEIF('📝 DATA ENTRY'!J6:J205,">0"),1),"")
A6: ▸ Shelf Impact (Stand-out on shelf) | B6: SI | C6: 30% | D6: =IFERROR(ROUND(AVERAGEIF('📝 DATA ENTRY'!K6:K205,">0"),1),"") | E6: =IFERROR(ROUND(AVERAGEIF('📝 DATA ENTRY'!L6:L205,">0"),1),"") | F6: =IFERROR(ROUND(AVERAGEIF('📝 DATA ENTRY'!M6:M205,">0"),1),"") | G6: =IFERROR(ROUND(AVERAGEIF('📝 DATA ENTRY'!N6:N205,">0"),1),"")
A7: ▸ Color Contrast (Visual differentiation) | B7: CC | C7: 20% | D7: =IFERROR(ROUND(AVERAGEIF('📝 DATA ENTRY'!O6:O205,">0"),1),"") | E7: =IFERROR(ROUND(AVERAGEIF('📝 DATA ENTRY'!P6:P205,">0"),1),"") | F7: =IFERROR(ROUND(AVERAGEIF('📝 DATA ENTRY'!Q6:Q205,">0"),1),"") | G7: =IFERROR(ROUND(AVERAGEIF('📝 DATA ENTRY'!R6:R205,">0"),1),"")
A8: ▸ Distance Recognition (5–10 feet) | B8: DR | C8: 20% | D8: =IFERROR(ROUND(AVERAGEIF('📝 DATA ENTRY'!S6:S205,">0"),1),"") | E8: =IFERROR(ROUND(AVERAGEIF('📝 DATA ENTRY'!T6:T205,">0"),1),"") | F8: =IFERROR(ROUND(AVERAGEIF('📝 DATA ENTRY'!U6:U205,">0"),1),"") | G8: =IFERROR(ROUND(AVERAGEIF('📝 DATA ENTRY'!V6:V205,">0"),1),"")
A9: ★ VISIBILITY SCORE (Weighted) | C9: 25% of PES | D9: =IFERROR(ROUND(D5*0.3+D6*0.3+D7*0.2+D8*0.2,1),"") | E9: =IFERROR(ROUND(E5*0.3+E6*0.3+E7*0.2+E8*0.2,1),"") | F9: =IFERROR(ROUND(F5*0.3+F6*0.3+F7*0.2+F8*0.2,1),"") | G9: =IFERROR(ROUND(G5*0.3+G6*0.3+G7*0.2+G8*0.2,1),"")
A11: 🟠 DIMENSION 2: PREMIUM FEEL
A12: ▸ Luxury Appeal (Aspirational look) | B12: LA | C12: 25% | D12: =IFERROR(ROUND(AVERAGEIF('📝 DATA ENTRY'!W6:W205,">0"),1),"") | E12: =IFERROR(ROUND(AVERAGEIF('📝 DATA ENTRY'!X6:X205,">0"),1),"") | F12: =IFERROR(ROUND(AVERAGEIF('📝 DATA ENTRY'!Y6:Y205,">0"),1),"") | G12: =IFERROR(ROUND(AVERAGEIF('📝 DATA ENTRY'!Z6:Z205,">0"),1),"")
A13: ▸ Design Sophistication (Modernity) | B13: DS | C13: 25% | D13: =IFERROR(ROUND(AVERAGEIF('📝 DATA ENTRY'!AA6:AA205,">0"),1),"") | E13: =IFERROR(ROUND(AVERAGEIF('📝 DATA ENTRY'!AB6:AB205,">0"),1),"") | F13: =IFERROR(ROUND(AVERAGEIF('📝 DATA ENTRY'!AC6:AC205,">0"),1),"") | G13: =IFERROR(ROUND(AVERAGEIF('📝 DATA ENTRY'!AD6:AD205,">0"),1),"")
A14: ▸ Premium Cues (Metallics, gradients, typo) | B14: PC | C14: 25% | D14: =IFERROR(ROUND(AVERAGEIF('📝 DATA ENTRY'!AE6:AE205,">0"),1),"") | E14: =IFERROR(ROUND(AVERAGEIF('📝 DATA ENTRY'!AF6:AF205,">0"),1),"") | F14: =IFERROR(ROUND(AVERAGEIF('📝 DATA ENTRY'!AG6:AG205,">0"),1),"") | G14: =IFERROR(ROUND(AVERAGEIF('📝 DATA ENTRY'!AH6:AH205,">0"),1),"")
A15: ▸ Trust Perception (Reliability signals) | B15: TP | C15: 25% | D15: =IFERROR(ROUND(AVERAGEIF('📝 DATA ENTRY'!AI6:AI205,">0"),1),"") | E15: =IFERROR(ROUND(AVERAGEIF('📝 DATA ENTRY'!AJ6:AJ205,">0"),1),"") | F15: =IFERROR(ROUND(AVERAGEIF('📝 DATA ENTRY'!AK6:AK205,">0"),1),"") | G15: =IFERROR(ROUND(AVERAGEIF('📝 DATA ENTRY'!AL6:AL205,">0"),1),"")
A16: ★ PREMIUM FEEL SCORE (Weighted) | C16: 25% of PES | D16: =IFERROR(ROUND(D12*0.25+D13*0.25+D14*0.25+D15*0.25,1),"") | E16: =IFERROR(ROUND(E12*0.25+E13*0.25+E14*0.25+E15*0.25,1),"") | F16: =IFERROR(ROUND(F12*0.25+F13*0.25+F14*0.25+F15*0.25,1),"") | G16: =IFERROR(ROUND(G12*0.25+G13*0.25+G14*0.25+G15*0.25,1),"")
A18: 🟢 DIMENSION 3: SKU CLARITY
A19: ▸ Variant Differentiation (SKU to SKU) | B19: VD | C19: 30% | D19: =IFERROR(ROUND(AVERAGEIF('📝 DATA ENTRY'!AM6:AM205,">0"),1),"") | E19: =IFERROR(ROUND(AVERAGEIF('📝 DATA ENTRY'!AN6:AN205,">0"),1),"") | F19: =IFERROR(ROUND(AVERAGEIF('📝 DATA ENTRY'!AO6:AO205,">0"),1),"") | G19: =IFERROR(ROUND(AVERAGEIF('📝 DATA ENTRY'!AP6:AP205,">0"),1),"")
A20: ▸ Segment Differentiation (Economy/Premium/Luxury) | B20: SD | C20: 25% | D20: =IFERROR(ROUND(AVERAGEIF('📝 DATA ENTRY'!AQ6:AQ205,">0"),1),"") | E20: =IFERROR(ROUND(AVERAGEIF('📝 DATA ENTRY'!AR6:AR205,">0"),1),"") | F20: =IFERROR(ROUND(AVERAGEIF('📝 DATA ENTRY'!AS6:AS205,">0"),1),"") | G20: =IFERROR(ROUND(AVERAGEIF('📝 DATA ENTRY'!AT6:AT205,">0"),1),"")
A21: ▸ Color Coding Logic (Visual navigation ease) | B21: CL | C21: 25% | D21: =IFERROR(ROUND(AVERAGEIF('📝 DATA ENTRY'!AU6:AU205,">0"),1),"") | E21: =IFERROR(ROUND(AVERAGEIF('📝 DATA ENTRY'!AV6:AV205,">0"),1),"") | F21: =IFERROR(ROUND(AVERAGEIF('📝 DATA ENTRY'!AW6:AW205,">0"),1),"") | G21: =IFERROR(ROUND(AVERAGEIF('📝 DATA ENTRY'!AX6:AX205,">0"),1),"")
A22: ▸ Naming Structure (Product name clarity) | B22: NS | C22: 20% | D22: =IFERROR(ROUND(AVERAGEIF('📝 DATA ENTRY'!AY6:AY205,">0"),1),"") | E22: =IFERROR(ROUND(AVERAGEIF('📝 DATA ENTRY'!AZ6:AZ205,">0"),1),"") | F22: =IFERROR(ROUND(AVERAGEIF('📝 DATA ENTRY'!BA6:BA205,">0"),1),"") | G22: =IFERROR(ROUND(AVERAGEIF('📝 DATA ENTRY'!BB6:BB205,">0"),1),"")
A23: ★ SKU CLARITY SCORE (Weighted) | C23: 25% of PES | D23: =IFERROR(ROUND(D19*0.3+D20*0.25+D21*0.25+D22*0.2,1),"") | E23: =IFERROR(ROUND(E19*0.3+E20*0.25+E21*0.25+E22*0.2,1),"") | F23: =IFERROR(ROUND(F19*0.3+F20*0.25+F21*0.25+F22*0.2,1),"") | G23: =IFERROR(ROUND(G19*0.3+G20*0.25+G21*0.25+G22*0.2,1),"")
A25: 🔵 DIMENSION 4: COMMUNICATION EFFECTIVENESS
A26: ▸ Product Type Clarity (Interior/Exterior/Primer) | B26: PT | C26: 25% | D26: =IFERROR(ROUND(AVERAGEIF('📝 DATA ENTRY'!BC6:BC205,">0"),1),"") | E26: =IFERROR(ROUND(AVERAGEIF('📝 DATA ENTRY'!BD6:BD205,">0"),1),"") | F26: =IFERROR(ROUND(AVERAGEIF('📝 DATA ENTRY'!BE6:BE205,">0"),1),"") | G26: =IFERROR(ROUND(AVERAGEIF('📝 DATA ENTRY'!BF6:BF205,">0"),1),"")
A27: ▸ Benefit Communication (Claims visibility) | B27: BC | C27: 25% | D27: =IFERROR(ROUND(AVERAGEIF('📝 DATA ENTRY'!BG6:BG205,">0"),1),"") | E27: =IFERROR(ROUND(AVERAGEIF('📝 DATA ENTRY'!BH6:BH205,">0"),1),"") | F27: =IFERROR(ROUND(AVERAGEIF('📝 DATA ENTRY'!BI6:BI205,">0"),1),"") | G27: =IFERROR(ROUND(AVERAGEIF('📝 DATA ENTRY'!BJ6:BJ205,">0"),1),"")
A28: ▸ Information Hierarchy (Logical flow) | B28: IH | C28: 25% | D28: =IFERROR(ROUND(AVERAGEIF('📝 DATA ENTRY'!BK6:BK205,">0"),1),"") | E28: =IFERROR(ROUND(AVERAGEIF('📝 DATA ENTRY'!BL6:BL205,">0"),1),"") | F28: =IFERROR(ROUND(AVERAGEIF('📝 DATA ENTRY'!BM6:BM205,">0"),1),"") | G28: =IFERROR(ROUND(AVERAGEIF('📝 DATA ENTRY'!BN6:BN205,">0"),1),"")
A29: ▸ Readability (Ease of understanding text) | B29: RD | C29: 25% | D29: =IFERROR(ROUND(AVERAGEIF('📝 DATA ENTRY'!BO6:BO205,">0"),1),"") | E29: =IFERROR(ROUND(AVERAGEIF('📝 DATA ENTRY'!BP6:BP205,">0"),1),"") | F29: =IFERROR(ROUND(AVERAGEIF('📝 DATA ENTRY'!BQ6:BQ205,">0"),1),"") | G29: =IFERROR(ROUND(AVERAGEIF('📝 DATA ENTRY'!BR6:BR205,">0"),1),"")
A30: ★ COMMUNICATION EFFECTIVENESS SCORE (Weighted) | C30: 25% of PES | D30: =IFERROR(ROUND(D26*0.25+D27*0.25+D28*0.25+D29*0.25,1),"") | E30: =IFERROR(ROUND(E26*0.25+E27*0.25+E28*0.25+E29*0.25,1),"") | F30: =IFERROR(ROUND(F26*0.25+F27*0.25+F28*0.25+F29*0.25,1),"") | G30: =IFERROR(ROUND(G26*0.25+G27*0.25+G28*0.25+G29*0.25,1),"")
A32: 🏆 PACKAGING EFFECTIVENESS SCORE (PES) — Max 10 | D32: =IFERROR(ROUND((D9*0.25+D16*0.25+D23*0.25+D30*0.25),1),"") | E32: =IFERROR(ROUND((E9*0.25+E16*0.25+E23*0.25+E30*0.25),1),"") | F32: =IFERROR(ROUND((F9*0.25+F16*0.25+F23*0.25+F30*0.25),1),"") | G32: =IFERROR(ROUND((G9*0.25+G16*0.25+G23*0.25+G30*0.25),1),"")
A34: 📏 PES Interpretation Scale
A35: 9.0–10.0 | B35: Best-in-Class Packaging
A36: 8.0–8.9 | B36: Strong Packaging System
A37: 7.0–7.9 | B37: Competitive — Needs Improvement
A38: 6.0–6.9 | B38: Significant Improvement Required
A39: Below 6.0 | B39: Weak Packaging Performance

Sheet 🏆 Benchmarking
A1: 🏆 BENCHMARKING FRAMEWORK — 25 Parameters × 5 Pillars × 4 Brands — Auto-Calculated
A2: PEI Score = Average of 5 Pillar Scores (each pillar = average of its 5 parameters) | All scores auto-pulled from DATA ENTRY sheet
A3: Pillar | C3: Parameter | D3: Asian Paints | E3: Birla Opus | F3: Dulux Paints | G3: JSW Paints | H3: Business Impact
A4: ★ VISUAL IDENTITY (Weight: 20%)
A5: Visual Identity | B5: BViz | C5: Brand Visibility (Logo prominence) | D5: =IFERROR(ROUND(AVERAGEIF('📝 DATA ENTRY'!BS6:BS205,">0"),1),"") -> 8.5 | E5: =IFERROR(ROUND(AVERAGEIF('📝 DATA ENTRY'!BT6:BT205,">0"),1),"") | F5: =IFERROR(ROUND(AVERAGEIF('📝 DATA ENTRY'!BU6:BU205,">0"),1),"") | G5: =IFERROR(ROUND(AVERAGEIF('📝 DATA ENTRY'!BV6:BV205,">0"),1),"") | H5: Brand Recall
A6: Visual Identity | B6: DM | C6: Design Modernity | D6: =IFERROR(ROUND(AVERAGEIF('📝 DATA ENTRY'!BW6:BW205,">0"),1),"") | E6: =IFERROR(ROUND(AVERAGEIF('📝 DATA ENTRY'!BX6:BX205,">0"),1),"") | F6: =IFERROR(ROUND(AVERAGEIF('📝 DATA ENTRY'!BY6:BY205,">0"),1),"") | G6: =IFERROR(ROUND(AVERAGEIF('📝 DATA ENTRY'!BZ6:BZ205,">0"),1),"") | H6: Modern Appeal
A7: Visual Identity | B7: TR | C7: Typography Readability | D7: =IFERROR(ROUND(AVERAGEIF('📝 DATA ENTRY'!CA6:CA205,">0"),1),"") | E7: =IFERROR(ROUND(AVERAGEIF('📝 DATA ENTRY'!CB6:CB205,">0"),1),"") | F7: =IFERROR(ROUND(AVERAGEIF('📝 DATA ENTRY'!CC6:CC205,">0"),1),"") | G7: =IFERROR(ROUND(AVERAGEIF('📝 DATA ENTRY'!CD6:CD205,">0"),1),"") | H7: Consumer Understanding
A8: Visual Identity | B8: ColC | C8: Color Consistency with brand | D8: =IFERROR(ROUND(AVERAGEIF('📝 DATA ENTRY'!CE6:CE205,">0"),1),"") | E8: =IFERROR(ROUND(AVERAGEIF('📝 DATA ENTRY'!CF6:CF205,">0"),1),"") | F8: =IFERROR(ROUND(AVERAGEIF('📝 DATA ENTRY'!CG6:CG205,">0"),1),"") | G8: =IFERROR(ROUND(AVERAGEIF('📝 DATA ENTRY'!CH6:CH205,">0"),1),"") | H8: Brand Recognition
A9: Visual Identity | B9: VA | C9: Visual Appeal (Overall attractiveness) | D9: =IFERROR(ROUND(AVERAGEIF('📝 DATA ENTRY'!CI6:CI205,">0"),1),"") | E9: =IFERROR(ROUND(AVERAGEIF('📝 DATA ENTRY'!CJ6:CJ205,">0"),1),"") | F9: =IFERROR(ROUND(AVERAGEIF('📝 DATA ENTRY'!CK6:CK205,">0"),1),"") | G9: =IFERROR(ROUND(AVERAGEIF('📝 DATA ENTRY'!CL6:CL205,">0"),1),"") | H9: Purchase Attraction
A10: ★ Visual Identity PILLAR SCORE (Avg of 5 params) | D10: =IFERROR(ROUND(AVERAGE(D5,D6,D7,D8,D9),1),"") -> 8.5 | E10: =IFERROR(ROUND(AVERAGE(E5,E6,E7,E8,E9),1),"") | F10: =IFERROR(ROUND(AVERAGE(F5,F6,F7,F8,F9),1),"") | G10: =IFERROR(ROUND(AVERAGE(G5,G6,G7,G8,G9),1),"")
A12: ★ COMMUNICATION (Weight: 20%)
A13: Communication | B13: PCC | C13: Product Category Clarity (Int/Ext/Primer) | D13: =IFERROR(ROUND(AVERAGEIF('📝 DATA ENTRY'!CM6:CM205,">0"),1),"") | E13: =IFERROR(ROUND(AVERAGEIF('📝 DATA ENTRY'!CN6:CN205,">0"),1),"") | F13: =IFERROR(ROUND(AVERAGEIF('📝 DATA ENTRY'!CO6:CO205,">0"),1),"") | G13: =IFERROR(ROUND(AVERAGEIF('📝 DATA ENTRY'!CP6:CP205,">0"),1),"") | H13: Faster Decision Making
A14: Communication | B14: BenV | C14: Benefit Visibility (Claims on pack) | D14: =IFERROR(ROUND(AVERAGEIF('📝 DATA ENTRY'!CQ6:CQ205,">0"),1),"") | E14: =IFERROR(ROUND(AVERAGEIF('📝 DATA ENTRY'!CR6:CR205,">0"),1),"") | F14: =IFERROR(ROUND(AVERAGEIF('📝 DATA ENTRY'!CS6:CS205,">0"),1),"") | G14: =IFERROR(ROUND(AVERAGEIF('📝 DATA ENTRY'!CT6:CT205,">0"),1),"") | H14: Claim Effectiveness
A15: Communication | B15: FC | C15: Finish Communication (Matte/Gloss/Satin) | D15: =IFERROR(ROUND(AVERAGEIF('📝 DATA ENTRY'!CU6:CU205,">0"),1),"") | E15: =IFERROR(ROUND(AVERAGEIF('📝 DATA ENTRY'!CV6:CV205,">0"),1),"") | F15: =IFERROR(ROUND(AVERAGEIF('📝 DATA ENTRY'!CW6:CW205,">0"),1),"") | G15: =IFERROR(ROUND(AVERAGEIF('📝 DATA ENTRY'!CX6:CX205,">0"),1),"") | H15: Product Selection Ease
A16: Communication | B16: InfoH | C16: Information Hierarchy | D16: =IFERROR(ROUND(AVERAGEIF('📝 DATA ENTRY'!CY6:CY205,">0"),1),"") | E16: =IFERROR(ROUND(AVERAGEIF('📝 DATA ENTRY'!CZ6:CZ205,">0"),1),"") | F16: =IFERROR(ROUND(AVERAGEIF('📝 DATA ENTRY'!DA6:DA205,">0"),1),"") | G16: =IFERROR(ROUND(AVERAGEIF('📝 DATA ENTRY'!DB6:DB205,">0"),1),"") | H16: Comprehension
A17: Communication | B17: Read | C17: Readability of communication | D17: =IFERROR(ROUND(AVERAGEIF('📝 DATA ENTRY'!DC6:DC205,">0"),1),"") | E17: =IFERROR(ROUND(AVERAGEIF('📝 DATA ENTRY'!DD6:DD205,">0"),1),"") | F17: =IFERROR(ROUND(AVERAGEIF('📝 DATA ENTRY'!DE6:DE205,">0"),1),"") | G17: =IFERROR(ROUND(AVERAGEIF('📝 DATA ENTRY'!DF6:DF205,">0"),1),"") | H17: Consumer Understanding
A18: ★ Communication PILLAR SCORE (Avg of 5 params) | D18: =IFERROR(ROUND(AVERAGE(D13,D14,D15,D16,D17),1),"") | E18: =IFERROR(ROUND(AVERAGE(E13,E14,E15,E16,E17),1),"") | F18: =IFERROR(ROUND(AVERAGE(F13,F14,F15,F16,F17),1),"") | G18: =IFERROR(ROUND(AVERAGE(G13,G14,G15,G16,G17),1),"")
A20: ★ SKU ARCHITECTURE (Weight: 20%)
A21: SKU Architecture | B21: VarD | C21: Variant Differentiation | D21: =IFERROR(ROUND(AVERAGEIF('📝 DATA ENTRY'!DG6:DG205,">0"),1),"") | E21: =IFERROR(ROUND(AVERAGEIF('📝 DATA ENTRY'!DH6:DH205,">0"),1),"") | F21: =IFERROR(ROUND(AVERAGEIF('📝 DATA ENTRY'!DI6:DI205,">0"),1),"") | G21: =IFERROR(ROUND(AVERAGEIF('📝 DATA ENTRY'!DJ6:DJ205,">0"),1),"") | H21: Reduced Confusion
A22: SKU Architecture | B22: SegD | C22: Segment Differentiation (Luxury/Economy) | D22: =IFERROR(ROUND(AVERAGEIF('📝 DATA ENTRY'!DK6:DK205,">0"),1),"") | E22: =IFERROR(ROUND(AVERAGEIF('📝 DATA ENTRY'!DL6:DL205,">0"),1),"") | F22: =IFERROR(ROUND(AVERAGEIF('📝 DATA ENTRY'!DM6:DM205,">0"),1),"") | G22: =IFERROR(ROUND(AVERAGEIF('📝 DATA ENTRY'!DN6:DN205,">0"),1),"") | H22: Portfolio Clarity
A23: SKU Architecture | B23: CCL | C23: Colour Coding Logic | D23: =IFERROR(ROUND(AVERAGEIF('📝 DATA ENTRY'!DO6:DO205,">0"),1),"") | E23: =IFERROR(ROUND(AVERAGEIF('📝 DATA ENTRY'!DP6:DP205,">0"),1),"") | F23: =IFERROR(ROUND(AVERAGEIF('📝 DATA ENTRY'!DQ6:DQ205,">0"),1),"") | G23: =IFERROR(ROUND(AVERAGEIF('📝 DATA ENTRY'!DR6:DR205,">0"),1),"") | H23: SKU Navigation
A24: SKU Architecture | B24: NamS | C24: Naming Structure | D24: =IFERROR(ROUND(AVERAGEIF('📝 DATA ENTRY'!DS6:DS205,">0"),1),"") | E24: =IFERROR(ROUND(AVERAGEIF('📝 DATA ENTRY'!DT6:DT205,">0"),1),"") | F24: =IFERROR(ROUND(AVERAGEIF('📝 DATA ENTRY'!DU6:DU205,">0"),1),"") | G24: =IFERROR(ROUND(AVERAGEIF('📝 DATA ENTRY'!DV6:DV205,">0"),1),"") | H24: Recommendation Ease
A25: SKU Architecture | B25: PortC | C25: Portfolio Consistency | D25: =IFERROR(ROUND(AVERAGEIF('📝 DATA ENTRY'!DW6:DW205,">0"),1),"") | E25: =IFERROR(ROUND(AVERAGEIF('📝 DATA ENTRY'!DX6:DX205,">0"),1),"") | F25: =IFERROR(ROUND(AVERAGEIF('📝 DATA ENTRY'!DY6:DY205,">0"),1),"") | G25: =IFERROR(ROUND(AVERAGEIF('📝 DATA ENTRY'!DZ6:DZ205,">0"),1),"") | H25: Brand Consistency
A26: ★ SKU Architecture PILLAR SCORE (Avg of 5 params) | D26: =IFERROR(ROUND(AVERAGE(D21,D22,D23,D24,D25),1),"") | E26: =IFERROR(ROUND(AVERAGE(E21,E22,E23,E24,E25),1),"") | F26: =IFERROR(ROUND(AVERAGE(F21,F22,F23,F24,F25),1),"") | G26: =IFERROR(ROUND(AVERAGE(G21,G22,G23,G24,G25),1),"")
A28: ★ RETAIL & TRADE (Weight: 20%)
A29: Retail & Trade | B29: ShV | C29: Shelf Visibility | D29: =IFERROR(ROUND(AVERAGEIF('📝 DATA ENTRY'!EA6:EA205,">0"),1),"") | E29: =IFERROR(ROUND(AVERAGEIF('📝 DATA ENTRY'!EB6:EB205,">0"),1),"") | F29: =IFERROR(ROUND(AVERAGEIF('📝 DATA ENTRY'!EC6:EC205,">0"),1),"") | G29: =IFERROR(ROUND(AVERAGEIF('📝 DATA ENTRY'!ED6:ED205,">0"),1),"") | H29: Retail Impact
A30: Retail & Trade | B30: DistR | C30: Distance Recognition | D30: =IFERROR(ROUND(AVERAGEIF('📝 DATA ENTRY'!EE6:EE205,">0"),1),"") | E30: =IFERROR(ROUND(AVERAGEIF('📝 DATA ENTRY'!EF6:EF205,">0"),1),"") | F30: =IFERROR(ROUND(AVERAGEIF('📝 DATA ENTRY'!EG6:EG205,">0"),1),"") | G30: =IFERROR(ROUND(AVERAGEIF('📝 DATA ENTRY'!EH6:EH205,">0"),1),"") | H30: Store Visibility
A31: Retail & Trade | B31: DRE | C31: Dealer Recommendation Ease | D31: =IFERROR(ROUND(AVERAGEIF('📝 DATA ENTRY'!EI6:EI205,">0"),1),"") | E31: =IFERROR(ROUND(AVERAGEIF('📝 DATA ENTRY'!EJ6:EJ205,">0"),1),"") | F31: =IFERROR(ROUND(AVERAGEIF('📝 DATA ENTRY'!EK6:EK205,">0"),1),"") | G31: =IFERROR(ROUND(AVERAGEIF('📝 DATA ENTRY'!EL6:EL205,">0"),1),"") | H31: Sales Conversion
A32: Retail & Trade | B32: ConR | C32: Contractor Recognition | D32: =IFERROR(ROUND(AVERAGEIF('📝 DATA ENTRY'!EM6:EM205,">0"),1),"") | E32: =IFERROR(ROUND(AVERAGEIF('📝 DATA ENTRY'!EN6:EN205,">0"),1),"") | F32: =IFERROR(ROUND(AVERAGEIF('📝 DATA ENTRY'!EO6:EO205,">0"),1),"") | G32: =IFERROR(ROUND(AVERAGEIF('📝 DATA ENTRY'!EP6:EP205,">0"),1),"") | H32: Contractor Recall
A33: Retail & Trade | B33: PRS | C33: Product Retrieval Speed | D33: =IFERROR(ROUND(AVERAGEIF('📝 DATA ENTRY'!EQ6:EQ205,">0"),1),"") | E33: =IFERROR(ROUND(AVERAGEIF('📝 DATA ENTRY'!ER6:ER205,">0"),1),"") | F33: =IFERROR(ROUND(AVERAGEIF('📝 DATA ENTRY'!ES6:ES205,">0"),1),"") | G33: =IFERROR(ROUND(AVERAGEIF('📝 DATA ENTRY'!ET6:ET205,">0"),1),"") | H33: Operational Efficiency
A34: ★ Retail & Trade PILLAR SCORE (Avg of 5 params) | D34: =IFERROR(ROUND(AVERAGE(D29,D30,D31,D32,D33),1),"") | E34: =IFERROR(ROUND(AVERAGE(E29,E30,E31,E32,E33),1),"") | F34: =IFERROR(ROUND(AVERAGE(F29,F30,F31,F32,F33),1),"") | G34: =IFERROR(ROUND(AVERAGE(G29,G30,G31,G32,G33),1),"")
A36: ★ PREMIUM PERCEPTION (Weight: 20%)
A37: Premium Perception | B37: LuxA | C37: Luxury Appeal | D37: =IFERROR(ROUND(AVERAGEIF('📝 DATA ENTRY'!EU6:EU205,">0"),1),"") | E37: =IFERROR(ROUND(AVERAGEIF('📝 DATA ENTRY'!EV6:EV205,">0"),1),"") | F37: =IFERROR(ROUND(AVERAGEIF('📝 DATA ENTRY'!EW6:EW205,">0"),1),"") | G37: =IFERROR(ROUND(AVERAGEIF('📝 DATA ENTRY'!EX6:EX205,">0"),1),"") | H37: Premium Positioning
A38: Premium Perception | B38: TrustP | C38: Trust Perception | D38: =IFERROR(ROUND(AVERAGEIF('📝 DATA ENTRY'!EY6:EY205,">0"),1),"") | E38: =IFERROR(ROUND(AVERAGEIF('📝 DATA ENTRY'!EZ6:EZ205,">0"),1),"") | F38: =IFERROR(ROUND(AVERAGEIF('📝 DATA ENTRY'!FA6:FA205,">0"),1),"") | G38: =IFERROR(ROUND(AVERAGEIF('📝 DATA ENTRY'!FB6:FB205,">0"),1),"") | H38: Brand Trust
A39: Premium Perception | B39: EmoA | C39: Emotional Appeal | D39: =IFERROR(ROUND(AVERAGEIF('📝 DATA ENTRY'!FC6:FC205,">0"),1),"") | E39: =IFERROR(ROUND(AVERAGEIF('📝 DATA ENTRY'!FD6:FD205,">0"),1),"") | F39: =IFERROR(ROUND(AVERAGEIF('📝 DATA ENTRY'!FE6:FE205,">0"),1),"") | G39: =IFERROR(ROUND(AVERAGEIF('📝 DATA ENTRY'!FF6:FF205,">0"),1),"") | H39: Purchase Intent
A40: Premium Perception | B40: MatP | C40: Material/Pack Quality Perception | D40: =IFERROR(ROUND(AVERAGEIF('📝 DATA ENTRY'!FG6:FG205,">0"),1),"") | E40: =IFERROR(ROUND(AVERAGEIF('📝 DATA ENTRY'!FH6:FH205,">0"),1),"") | F40: =IFERROR(ROUND(AVERAGEIF('📝 DATA ENTRY'!FI6:FI205,">0"),1),"") | G40: =IFERROR(ROUND(AVERAGEIF('📝 DATA ENTRY'!FJ6:FJ205,">0"),1),"") | H40: Quality Perception
A41: Premium Perception | B41: ModA | C41: Modern Appearance | D41: =IFERROR(ROUND(AVERAGEIF('📝 DATA ENTRY'!FK6:FK205,">0"),1),"") | E41: =IFERROR(ROUND(AVERAGEIF('📝 DATA ENTRY'!FL6:FL205,">0"),1),"") | F41: =IFERROR(ROUND(AVERAGEIF('📝 DATA ENTRY'!FM6:FM205,">0"),1),"") | G41: =IFERROR(ROUND(AVERAGEIF('📝 DATA ENTRY'!FN6:FN205,">0"),1),"") | H41: Premium Image
A42: ★ Premium Perception PILLAR SCORE (Avg of 5 params) | D42: =IFERROR(ROUND(AVERAGE(D37,D38,D39,D40,D41),1),"") | E42: =IFERROR(ROUND(AVERAGE(E37,E38,E39,E40,E41),1),"") | F42: =IFERROR(ROUND(AVERAGE(F37,F38,F39,F40,F41),1),"") | G42: =IFERROR(ROUND(AVERAGE(G37,G38,G39,G40,G41),1),"")
A44: 🏅 PACKAGING EFFECTIVENESS INDEX (PEI) — Avg of 5 Pillars × 20% each — Max 10 | D44: =IFERROR(ROUND(AVERAGE(D10,D18,D26,D34,D42),1),"") -> 8.5 | E44: =IFERROR(ROUND(AVERAGE(E10,E18,E26,E34,E42),1),"") | F44: =IFERROR(ROUND(AVERAGE(F10,F18,F26,F34,F42),1),"") | G44: =IFERROR(ROUND(AVERAGE(G10,G18,G26,G34,G42),1),"")

Sheet 📈 Ranking Analysis
A1: 📈 BRAND RANKING ANALYSIS — Rank 1=5pts | Rank 2=3pts | Rank 3=1pt | Auto-aggregated
A2: Formula: Ranking Score = (Count of Rank-1 mentions × 5) + (Count of Rank-2 mentions × 3) + (Count of Rank-3 mentions × 1) ÷ Max possible
A3: Ranking Dimension | B3: Brand | C3: Rank-1 Count | D3: Rank-2 Count | E3: Rank-3 Count | F3: Raw Score (5+3+1) | G3: Normalized (/10) | H3: Rank Position
A4: ◆ Shelf Visibility — Which brand stands out most?
A5: Shelf Visibility — Which brand stands out most? | B5: Asian Paints | C5: =COUNTIF('📝 DATA ENTRY'!FO6:FO205,"Asian Paints") -> 0 | D5: =COUNTIF('📝 DATA ENTRY'!FP6:FP205,"Asian Paints") -> 0 | E5: =COUNTIF('📝 DATA ENTRY'!FQ6:FQ205,"Asian Paints") -> 0 | F5: =C5*5+D5*3+E5*1 -> 0 | G5: =IFERROR(ROUND(F5/MAX(F5:F8)*10,1),"") | H5: =IFERROR(RANK(G5,G5:G8,0),"")
A6: Shelf Visibility — Which brand stands out most? | B6: Birla Opus | C6: =COUNTIF('📝 DATA ENTRY'!FO6:FO205,"Birla Opus") -> 0 | D6: =COUNTIF('📝 DATA ENTRY'!FP6:FP205,"Birla Opus") -> 0 | E6: =COUNTIF('📝 DATA ENTRY'!FQ6:FQ205,"Birla Opus") -> 0 | F6: =C6*5+D6*3+E6*1 -> 0 | G6: =IFERROR(ROUND(F6/MAX(F5:F8)*10,1),"") | H6: =IFERROR(RANK(G6,G5:G8,0),"")
A7: Shelf Visibility — Which brand stands out most? | B7: Dulux Paints | C7: =COUNTIF('📝 DATA ENTRY'!FO6:FO205,"Dulux Paints") -> 0 | D7: =COUNTIF('📝 DATA ENTRY'!FP6:FP205,"Dulux Paints") -> 0 | E7: =COUNTIF('📝 DATA ENTRY'!FQ6:FQ205,"Dulux Paints") -> 0 | F7: =C7*5+D7*3+E7*1 -> 0 | G7: =IFERROR(ROUND(F7/MAX(F5:F8)*10,1),"") | H7: =IFERROR(RANK(G7,G5:G8,0),"")
A8: Shelf Visibility — Which brand stands out most? | B8: JSW Paints | C8: =COUNTIF('📝 DATA ENTRY'!FO6:FO205,"JSW Paints") -> 0 | D8: =COUNTIF('📝 DATA ENTRY'!FP6:FP205,"JSW Paints") -> 0 | E8: =COUNTIF('📝 DATA ENTRY'!FQ6:FQ205,"JSW Paints") -> 0 | F8: =C8*5+D8*3+E8*1 -> 0 | G8: =IFERROR(ROUND(F8/MAX(F5:F8)*10,1),"") | H8: =IFERROR(RANK(G8,G5:G8,0),"")
A10: ◆ Premium Feel — Which brand looks most premium?
A11: Premium Feel — Which brand looks most premium? | B11: Asian Paints | C11: =COUNTIF('📝 DATA ENTRY'!FR6:FR205,"Asian Paints") -> 0 | D11: =COUNTIF('📝 DATA ENTRY'!FS6:FS205,"Asian Paints") -> 0 | E11: =COUNTIF('📝 DATA ENTRY'!FT6:FT205,"Asian Paints") -> 0 | F11: =C11*5+D11*3+E11*1 -> 0 | G11: =IFERROR(ROUND(F11/MAX(F11:F14)*10,1),"") | H11: =IFERROR(RANK(G11,G11:G14,0),"")
A12: Premium Feel — Which brand looks most premium? | B12: Birla Opus | C12: =COUNTIF('📝 DATA ENTRY'!FR6:FR205,"Birla Opus") -> 0 | D12: =COUNTIF('📝 DATA ENTRY'!FS6:FS205,"Birla Opus") -> 0 | E12: =COUNTIF('📝 DATA ENTRY'!FT6:FT205,"Birla Opus") -> 0 | F12: =C12*5+D12*3+E12*1 -> 0 | G12: =IFERROR(ROUND(F12/MAX(F11:F14)*10,1),"") | H12: =IFERROR(RANK(G12,G11:G14,0),"")
A13: Premium Feel — Which brand looks most premium? | B13: Dulux Paints | C13: =COUNTIF('📝 DATA ENTRY'!FR6:FR205,"Dulux Paints") -> 0 | D13: =COUNTIF('📝 DATA ENTRY'!FS6:FS205,"Dulux Paints") -> 0 | E13: =COUNTIF('📝 DATA ENTRY'!FT6:FT205,"Dulux Paints") -> 0 | F13: =C13*5+D13*3+E13*1 -> 0 | G13: =IFERROR(ROUND(F13/MAX(F11:F14)*10,1),"") | H13: =IFERROR(RANK(G13,G11:G14,0),"")
A14: Premium Feel — Which brand looks most premium? | B14: JSW Paints | C14: =COUNTIF('📝 DATA ENTRY'!FR6:FR205,"JSW Paints") -> 0 | D14: =COUNTIF('📝 DATA ENTRY'!FS6:FS205,"JSW Paints") -> 0 | E14: =COUNTIF('📝 DATA ENTRY'!FT6:FT205,"JSW Paints") -> 0 | F14: =C14*5+D14*3+E14*1 -> 0 | G14: =IFERROR(ROUND(F14/MAX(F11:F14)*10,1),"") | H14: =IFERROR(RANK(G14,G11:G14,0),"")
A16: ◆ SKU Clarity — Which brand is easiest to navigate?
A17: SKU Clarity — Which brand is easiest to navigate? | B17: Asian Paints | C17: =COUNTIF('📝 DATA ENTRY'!FU6:FU205,"Asian Paints") -> 0 | D17: =COUNTIF('📝 DATA ENTRY'!FV6:FV205,"Asian Paints") -> 0 | E17: =COUNTIF('📝 DATA ENTRY'!FW6:FW205,"Asian Paints") -> 0 | F17: =C17*5+D17*3+E17*1 -> 0 | G17: =IFERROR(ROUND(F17/MAX(F17:F20)*10,1),"") | H17: =IFERROR(RANK(G17,G17:G20,0),"")
A18: SKU Clarity — Which brand is easiest to navigate? | B18: Birla Opus | C18: =COUNTIF('📝 DATA ENTRY'!FU6:FU205,"Birla Opus") -> 0 | D18: =COUNTIF('📝 DATA ENTRY'!FV6:FV205,"Birla Opus") -> 0 | E18: =COUNTIF('📝 DATA ENTRY'!FW6:FW205,"Birla Opus") -> 0 | F18: =C18*5+D18*3+E18*1 -> 0 | G18: =IFERROR(ROUND(F18/MAX(F17:F20)*10,1),"") | H18: =IFERROR(RANK(G18,G17:G20,0),"")
A19: SKU Clarity — Which brand is easiest to navigate? | B19: Dulux Paints | C19: =COUNTIF('📝 DATA ENTRY'!FU6:FU205,"Dulux Paints") -> 0 | D19: =COUNTIF('📝 DATA ENTRY'!FV6:FV205,"Dulux Paints") -> 0 | E19: =COUNTIF('📝 DATA ENTRY'!FW6:FW205,"Dulux Paints") -> 0 | F19: =C19*5+D19*3+E19*1 -> 0 | G19: =IFERROR(ROUND(F19/MAX(F17:F20)*10,1),"") | H19: =IFERROR(RANK(G19,G17:G20,0),"")
A20: SKU Clarity — Which brand is easiest to navigate? | B20: JSW Paints | C20: =COUNTIF('📝 DATA ENTRY'!FU6:FU205,"JSW Paints") -> 0 | D20: =COUNTIF('📝 DATA ENTRY'!FV6:FV205,"JSW Paints") -> 0 | E20: =COUNTIF('📝 DATA ENTRY'!FW6:FW205,"JSW Paints") -> 0 | F20: =C20*5+D20*3+E20*1 -> 0 | G20: =IFERROR(ROUND(F20/MAX(F17:F20)*10,1),"") | H20: =IFERROR(RANK(G20,G17:G20,0),"")
A22: ◆ Communication — Which brand communicates best?
A23: Communication — Which brand communicates best? | B23: Asian Paints | C23: =COUNTIF('📝 DATA ENTRY'!FX6:FX205,"Asian Paints") -> 0 | D23: =COUNTIF('📝 DATA ENTRY'!FY6:FY205,"Asian Paints") -> 0 | E23: =COUNTIF('📝 DATA ENTRY'!FZ6:FZ205,"Asian Paints") -> 0 | F23: =C23*5+D23*3+E23*1 -> 0 | G23: =IFERROR(ROUND(F23/MAX(F23:F26)*10,1),"") | H23: =IFERROR(RANK(G23,G23:G26,0),"")
A24: Communication — Which brand communicates best? | B24: Birla Opus | C24: =COUNTIF('📝 DATA ENTRY'!FX6:FX205,"Birla Opus") -> 0 | D24: =COUNTIF('📝 DATA ENTRY'!FY6:FY205,"Birla Opus") -> 0 | E24: =COUNTIF('📝 DATA ENTRY'!FZ6:FZ205,"Birla Opus") -> 0 | F24: =C24*5+D24*3+E24*1 -> 0 | G24: =IFERROR(ROUND(F24/MAX(F23:F26)*10,1),"") | H24: =IFERROR(RANK(G24,G23:G26,0),"")
A25: Communication — Which brand communicates best? | B25: Dulux Paints | C25: =COUNTIF('📝 DATA ENTRY'!FX6:FX205,"Dulux Paints") -> 0 | D25: =COUNTIF('📝 DATA ENTRY'!FY6:FY205,"Dulux Paints") -> 0 | E25: =COUNTIF('📝 DATA ENTRY'!FZ6:FZ205,"Dulux Paints") -> 0 | F25: =C25*5+D25*3+E25*1 -> 0 | G25: =IFERROR(ROUND(F25/MAX(F23:F26)*10,1),"") | H25: =IFERROR(RANK(G25,G23:G26,0),"")
A26: Communication — Which brand communicates best? | B26: JSW Paints | C26: =COUNTIF('📝 DATA ENTRY'!FX6:FX205,"JSW Paints") -> 0 | D26: =COUNTIF('📝 DATA ENTRY'!FY6:FY205,"JSW Paints") -> 0 | E26: =COUNTIF('📝 DATA ENTRY'!FZ6:FZ205,"JSW Paints") -> 0 | F26: =C26*5+D26*3+E26*1 -> 0 | G26: =IFERROR(ROUND(F26/MAX(F23:F26)*10,1),"") | H26: =IFERROR(RANK(G26,G23:G26,0),"")
A28: ◆ Overall — Which brand has the best packaging overall?
A29: Overall — Which brand has the best packaging overall? | B29: Asian Paints | C29: =COUNTIF('📝 DATA ENTRY'!GA6:GA205,"Asian Paints") -> 0 | D29: =COUNTIF('📝 DATA ENTRY'!GB6:GB205,"Asian Paints") -> 0 | E29: =COUNTIF('📝 DATA ENTRY'!GC6:GC205,"Asian Paints") -> 0 | F29: =C29*5+D29*3+E29*1 -> 0 | G29: =IFERROR(ROUND(F29/MAX(F29:F32)*10,1),"") | H29: =IFERROR(RANK(G29,G29:G32,0),"")
A30: Overall — Which brand has the best packaging overall? | B30: Birla Opus | C30: =COUNTIF('📝 DATA ENTRY'!GA6:GA205,"Birla Opus") -> 0 | D30: =COUNTIF('📝 DATA ENTRY'!GB6:GB205,"Birla Opus") -> 0 | E30: =COUNTIF('📝 DATA ENTRY'!GC6:GC205,"Birla Opus") -> 0 | F30: =C30*5+D30*3+E30*1 -> 0 | G30: =IFERROR(ROUND(F30/MAX(F29:F32)*10,1),"") | H30: =IFERROR(RANK(G30,G29:G32,0),"")
A31: Overall — Which brand has the best packaging overall? | B31: Dulux Paints | C31: =COUNTIF('📝 DATA ENTRY'!GA6:GA205,"Dulux Paints") -> 0 | D31: =COUNTIF('📝 DATA ENTRY'!GB6:GB205,"Dulux Paints") -> 0 | E31: =COUNTIF('📝 DATA ENTRY'!GC6:GC205,"Dulux Paints") -> 0 | F31: =C31*5+D31*3+E31*1 -> 0 | G31: =IFERROR(ROUND(F31/MAX(F29:F32)*10,1),"") | H31: =IFERROR(RANK(G31,G29:G32,0),"")
A32: Overall — Which brand has the best packaging overall? | B32: JSW Paints | C32: =COUNTIF('📝 DATA ENTRY'!GA6:GA205,"JSW Paints") -> 0 | D32: =COUNTIF('📝 DATA ENTRY'!GB6:GB205,"JSW Paints") -> 0 | E32: =COUNTIF('📝 DATA ENTRY'!GC6:GC205,"JSW Paints") -> 0 | F32: =C32*5+D32*3+E32*1 -> 0 | G32: =IFERROR(ROUND(F32/MAX(F29:F32)*10,1),"") | H32: =IFERROR(RANK(G32,G29:G32,0),"")
A35: AVERAGE RANKING SCORES
B36: Asian Paints | C36: =IFERROR(ROUND(AVERAGE(F5,F11,F17,F23,F29),1),"") -> 0
B37: Birla Opus | C37: =IFERROR(ROUND(AVERAGE(F6,F12,F18,F24,F30),1),"") -> 0
B38: Dulux Paints | C38: =IFERROR(ROUND(AVERAGE(F7,F13,F19,F25,F31),1),"") -> 0
B39: JSW Paints | C39: =IFERROR(ROUND(AVERAGE(F8,F14,F20,F26,F32),1),"") -> 0

Sheet 🔢 Mention Frequency
A1: 🔢 BRAND MENTION FREQUENCY CODING — Method 1: Score = (Mentions ÷ Max Mentions) × 10
A2: COUNTIF pulls from DATA ENTRY mention columns. Formula: Brand Score = (Brand Count ÷ Highest Count among 4 brands) × 10
A3: Theme / Question | B3: Brand | C3: Mention Count | D3: Max Count (in theme) | E3: Frequency Score (/10) | F3: Rank in Theme
A4: ◆ Fastest Moving / Most Recommended by you
A5: Fastest Moving / Most Recommended by you | B5: Asian Paints | C5: =COUNTIF('📝 DATA ENTRY'!GD6:GD205,"Asian Paints") -> 0 | D5: =MAX(C5:C8) -> 0 | E5: =IFERROR(ROUND(C5/D5*10,1),"") | F5: =IFERROR(RANK(C5,C5:C8,0),"") -> 1
A6: Fastest Moving / Most Recommended by you | B6: Birla Opus | C6: =COUNTIF('📝 DATA ENTRY'!GD6:GD205,"Birla Opus") -> 0 | D6: =MAX(C5:C8) -> 0 | E6: =IFERROR(ROUND(C6/D6*10,1),"") | F6: =IFERROR(RANK(C6,C5:C8,0),"") -> 1
A7: Fastest Moving / Most Recommended by you | B7: Dulux Paints | C7: =COUNTIF('📝 DATA ENTRY'!GD6:GD205,"Dulux Paints") -> 0 | D7: =MAX(C5:C8) -> 0 | E7: =IFERROR(ROUND(C7/D7*10,1),"") | F7: =IFERROR(RANK(C7,C5:C8,0),"") -> 1
A8: Fastest Moving / Most Recommended by you | B8: JSW Paints | C8: =COUNTIF('📝 DATA ENTRY'!GD6:GD205,"JSW Paints") -> 0 | D8: =MAX(C5:C8) -> 0 | E8: =IFERROR(ROUND(C8/D8*10,1),"") | F8: =IFERROR(RANK(C8,C5:C8,0),"") -> 1
A10: ◆ First Noticed on Shelf (instinctive)
A11: First Noticed on Shelf (instinctive) | B11: Asian Paints | C11: =COUNTIF('📝 DATA ENTRY'!GE6:GE205,"Asian Paints") -> 0 | D11: =MAX(C11:C14) -> 0 | E11: =IFERROR(ROUND(C11/D11*10,1),"") | F11: =IFERROR(RANK(C11,C11:C14,0),"") -> 1
A12: First Noticed on Shelf (instinctive) | B12: Birla Opus | C12: =COUNTIF('📝 DATA ENTRY'!GE6:GE205,"Birla Opus") -> 0 | D12: =MAX(C11:C14) -> 0 | E12: =IFERROR(ROUND(C12/D12*10,1),"") | F12: =IFERROR(RANK(C12,C11:C14,0),"") -> 1
A13: First Noticed on Shelf (instinctive) | B13: Dulux Paints | C13: =COUNTIF('📝 DATA ENTRY'!GE6:GE205,"Dulux Paints") -> 0 | D13: =MAX(C11:C14) -> 0 | E13: =IFERROR(ROUND(C13/D13*10,1),"") | F13: =IFERROR(RANK(C13,C11:C14,0),"") -> 1
A14: First Noticed on Shelf (instinctive) | B14: JSW Paints | C14: =COUNTIF('📝 DATA ENTRY'!GE6:GE205,"JSW Paints") -> 0 | D14: =MAX(C11:C14) -> 0 | E14: =IFERROR(ROUND(C14/D14*10,1),"") | F14: =IFERROR(RANK(C14,C11:C14,0),"") -> 1
A16: ◆ Looks Most Premium
A17: Looks Most Premium | B17: Asian Paints | C17: =COUNTIF('📝 DATA ENTRY'!GF6:GF205,"Asian Paints") -> 0 | D17: =MAX(C17:C20) -> 0 | E17: =IFERROR(ROUND(C17/D17*10,1),"") | F17: =IFERROR(RANK(C17,C17:C20,0),"") -> 1
A18: Looks Most Premium | B18: Birla Opus | C18: =COUNTIF('📝 DATA ENTRY'!GF6:GF205,"Birla Opus") -> 0 | D18: =MAX(C17:C20) -> 0 | E18: =IFERROR(ROUND(C18/D18*10,1),"") | F18: =IFERROR(RANK(C18,C17:C20,0),"") -> 1
A19: Looks Most Premium | B19: Dulux Paints | C19: =COUNTIF('📝 DATA ENTRY'!GF6:GF205,"Dulux Paints") -> 0 | D19: =MAX(C17:C20) -> 0 | E19: =IFERROR(ROUND(C19/D19*10,1),"") | F19: =IFERROR(RANK(C19,C17:C20,0),"") -> 1
A20: Looks Most Premium | B20: JSW Paints | C20: =COUNTIF('📝 DATA ENTRY'!GF6:GF205,"JSW Paints") -> 0 | D20: =MAX(C17:C20) -> 0 | E20: =IFERROR(ROUND(C20/D20*10,1),"") | F20: =IFERROR(RANK(C20,C17:C20,0),"") -> 1
A22: ◆ Creates Highest Trust
A23: Creates Highest Trust | B23: Asian Paints | C23: =COUNTIF('📝 DATA ENTRY'!GG6:GG205,"Asian Paints") -> 0 | D23: =MAX(C23:C26) -> 0 | E23: =IFERROR(ROUND(C23/D23*10,1),"") | F23: =IFERROR(RANK(C23,C23:C26,0),"") -> 1
A24: Creates Highest Trust | B24: Birla Opus | C24: =COUNTIF('📝 DATA ENTRY'!GG6:GG205,"Birla Opus") -> 0 | D24: =MAX(C23:C26) -> 0 | E24: =IFERROR(ROUND(C24/D24*10,1),"") | F24: =IFERROR(RANK(C24,C23:C26,0),"") -> 1
A25: Creates Highest Trust | B25: Dulux Paints | C25: =COUNTIF('📝 DATA ENTRY'!GG6:GG205,"Dulux Paints") -> 0 | D25: =MAX(C23:C26) -> 0 | E25: =IFERROR(ROUND(C25/D25*10,1),"") | F25: =IFERROR(RANK(C25,C23:C26,0),"") -> 1
A26: Creates Highest Trust | B26: JSW Paints | C26: =COUNTIF('📝 DATA ENTRY'!GG6:GG205,"JSW Paints") -> 0 | D26: =MAX(C23:C26) -> 0 | E26: =IFERROR(ROUND(C26/D26*10,1),"") | F26: =IFERROR(RANK(C26,C23:C26,0),"") -> 1
A28: ◆ Easiest to Understand
A29: Easiest to Understand | B29: Asian Paints | C29: =COUNTIF('📝 DATA ENTRY'!GH6:GH205,"Asian Paints") -> 0 | D29: =MAX(C29:C32) -> 0 | E29: =IFERROR(ROUND(C29/D29*10,1),"") | F29: =IFERROR(RANK(C29,C29:C32,0),"") -> 1
A30: Easiest to Understand | B30: Birla Opus | C30: =COUNTIF('📝 DATA ENTRY'!GH6:GH205,"Birla Opus") -> 0 | D30: =MAX(C29:C32) -> 0 | E30: =IFERROR(ROUND(C30/D30*10,1),"") | F30: =IFERROR(RANK(C30,C29:C32,0),"") -> 1
A31: Easiest to Understand | B31: Dulux Paints | C31: =COUNTIF('📝 DATA ENTRY'!GH6:GH205,"Dulux Paints") -> 0 | D31: =MAX(C29:C32) -> 0 | E31: =IFERROR(ROUND(C31/D31*10,1),"") | F31: =IFERROR(RANK(C31,C29:C32,0),"") -> 1
A32: Easiest to Understand | B32: JSW Paints | C32: =COUNTIF('📝 DATA ENTRY'!GH6:GH205,"JSW Paints") -> 0 | D32: =MAX(C29:C32) -> 0 | E32: =IFERROR(ROUND(C32/D32*10,1),"") | F32: =IFERROR(RANK(C32,C29:C32,0),"") -> 1
A34: ◆ Most Confusing Packaging
A35: Most Confusing Packaging | B35: Asian Paints | C35: =COUNTIF('📝 DATA ENTRY'!GI6:GI205,"Asian Paints") -> 0 | D35: =MAX(C35:C38) -> 0 | E35: =IFERROR(ROUND(C35/D35*10,1),"") | F35: =IFERROR(RANK(C35,C35:C38,0),"") -> 1
A36: Most Confusing Packaging | B36: Birla Opus | C36: =COUNTIF('📝 DATA ENTRY'!GI6:GI205,"Birla Opus") -> 0 | D36: =MAX(C35:C38) -> 0 | E36: =IFERROR(ROUND(C36/D36*10,1),"") | F36: =IFERROR(RANK(C36,C35:C38,0),"") -> 1
A37: Most Confusing Packaging | B37: Dulux Paints | C37: =COUNTIF('📝 DATA ENTRY'!GI6:GI205,"Dulux Paints") -> 0 | D37: =MAX(C35:C38) -> 0 | E37: =IFERROR(ROUND(C37/D37*10,1),"") | F37: =IFERROR(RANK(C37,C35:C38,0),"") -> 1
A38: Most Confusing Packaging | B38: JSW Paints | C38: =COUNTIF('📝 DATA ENTRY'!GI6:GI205,"JSW Paints") -> 0 | D38: =MAX(C35:C38) -> 0 | E38: =IFERROR(ROUND(C38/D38*10,1),"") | F38: =IFERROR(RANK(C38,C35:C38,0),"") -> 1
A40: ◆ Looks Most Modern
A41: Looks Most Modern | B41: Asian Paints | C41: =COUNTIF('📝 DATA ENTRY'!GJ6:GJ205,"Asian Paints") -> 0 | D41: =MAX(C41:C44) -> 0 | E41: =IFERROR(ROUND(C41/D41*10,1),"") | F41: =IFERROR(RANK(C41,C41:C44,0),"") -> 1
A42: Looks Most Modern | B42: Birla Opus | C42: =COUNTIF('📝 DATA ENTRY'!GJ6:GJ205,"Birla Opus") -> 0 | D42: =MAX(C41:C44) -> 0 | E42: =IFERROR(ROUND(C42/D42*10,1),"") | F42: =IFERROR(RANK(C42,C41:C44,0),"") -> 1
A43: Looks Most Modern | B43: Dulux Paints | C43: =COUNTIF('📝 DATA ENTRY'!GJ6:GJ205,"Dulux Paints") -> 0 | D43: =MAX(C41:C44) -> 0 | E43: =IFERROR(ROUND(C43/D43*10,1),"") | F43: =IFERROR(RANK(C43,C41:C44,0),"") -> 1
A44: Looks Most Modern | B44: JSW Paints | C44: =COUNTIF('📝 DATA ENTRY'!GJ6:GJ205,"JSW Paints") -> 0 | D44: =MAX(C41:C44) -> 0 | E44: =IFERROR(ROUND(C44/D44*10,1),"") | F44: =IFERROR(RANK(C44,C41:C44,0),"") -> 1
A46: ◆ Would You Personally Recommend / Buy
A47: Would You Personally Recommend / Buy | B47: Asian Paints | C47: =COUNTIF('📝 DATA ENTRY'!GK6:GK205,"Asian Paints") -> 0 | D47: =MAX(C47:C50) -> 0 | E47: =IFERROR(ROUND(C47/D47*10,1),"") | F47: =IFERROR(RANK(C47,C47:C50,0),"") -> 1
...

Sheet 🎯 Master Summary
A1: 🎯 MASTER BENCHMARKING SUMMARY — Final Scores Across All Frameworks
A2: All scores auto-pulled from analysis sheets. This is the PPT-ready output. Respondent count shown for credibility.
A4: Brand | B4: PES (PEEF Score /10) | C4: PEI (Benchmarking /10) | D4: Ranking Score (/10) | E4: Mention Freq Score (/10) | F4: COMPOSITE INDEX (/10) | G4: Rank # | H4: Interpretation | I4: Respondent Count
A5: Asian Paints | B5: ='📊 PEEF Analysis'!D32 | C5: ='🏆 Benchmarking'!D44 -> 8.5 | D5: ='📈 Ranking Analysis'!C36 -> 0 | E5: ='🔢 Mention Frequency'!C54 -> 0 | F5: =IFERROR(ROUND(B5*0.4+C5*0.4+D5*0.1+E5*0.1,1),"") | G5: =IFERROR(RANK(F5,F5:F8,0),"") | H5: =IF(F5="","",IF(F5>=9,"🏆 Best-in-Class",IF(F5>=8,"✅ Strong Packaging",IF(F5>=7,"⚠️ Competitive — Improve",IF(F5>=6,"🔴 Needs Work","❌ Weak"))))) | I5: =COUNTA('📝 DATA ENTRY'!B6:B205) -> 0
A6: Birla Opus | B6: ='📊 PEEF Analysis'!E32 | C6: ='🏆 Benchmarking'!E44 | D6: ='📈 Ranking Analysis'!C37 -> 0 | E6: ='🔢 Mention Frequency'!C55 -> 0 | F6: =IFERROR(ROUND(B6*0.4+C6*0.4+D6*0.1+E6*0.1,1),"") | G6: =IFERROR(RANK(F6,F5:F8,0),"") | H6: =IF(F6="","",IF(F6>=9,"🏆 Best-in-Class",IF(F6>=8,"✅ Strong Packaging",IF(F6>=7,"⚠️ Competitive — Improve",IF(F6>=6,"🔴 Needs Work","❌ Weak"))))) | I6: =COUNTA('📝 DATA ENTRY'!B6:B205) -> 0
A7: Dulux Paints | B7: ='📊 PEEF Analysis'!F32 | C7: ='🏆 Benchmarking'!F44 | D7: ='📈 Ranking Analysis'!C38 -> 0 | E7: ='🔢 Mention Frequency'!C56 -> 0 | F7: =IFERROR(ROUND(B7*0.4+C7*0.4+D7*0.1+E7*0.1,1),"") | G7: =IFERROR(RANK(F7,F5:F8,0),"") | H7: =IF(F7="","",IF(F7>=9,"🏆 Best-in-Class",IF(F7>=8,"✅ Strong Packaging",IF(F7>=7,"⚠️ Competitive — Improve",IF(F7>=6,"🔴 Needs Work","❌ Weak"))))) | I7: =COUNTA('📝 DATA ENTRY'!B6:B205) -> 0
A8: JSW Paints | B8: ='📊 PEEF Analysis'!G32 | C8: ='🏆 Benchmarking'!G44 | D8: ='📈 Ranking Analysis'!C39 -> 0 | E8: ='🔢 Mention Frequency'!C57 -> 0 | F8: =IFERROR(ROUND(B8*0.4+C8*0.4+D8*0.1+E8*0.1,1),"") | G8: =IFERROR(RANK(F8,F5:F8,0),"") | H8: =IF(F8="","",IF(F8>=9,"🏆 Best-in-Class",IF(F8>=8,"✅ Strong Packaging",IF(F8>=7,"⚠️ Competitive — Improve",IF(F8>=6,"🔴 Needs Work","❌ Weak"))))) | I8: =COUNTA('📝 DATA ENTRY'!B6:B205) -> 0
A10: 📌 COMPOSITE INDEX FORMULA: (PES × 40%) + (PEI × 40%) + (Ranking Score × 10%) + (Mention Freq Score × 10%) | D & E columns: copy average normalized scores from 📈 Ranking Analysis (col G) and 🔢 Mention Frequency (col E) sheets
A12: 📏 INTERPRETATION: 9.0–10.0 = Best-in-Class | 8.0–8.9 = Strong | 7.0–7.9 = Competitive | 6.0–6.9 = Needs Improvement | <6.0 = Weak
A13: TARGET SAMPLE: Dealers/Retailers: 15–20 | Distributors: 5–10 | Wholesalers: 5–10 | Contractors: 15–20 | Consumers: 20–30 | Architects: 5–10 | Total: ~70–100 observers
