Workbook

Sheet 📋 Instructions
B1: 🎨 PAINT PACKAGING BENCHMARKING — QUALITATIVE RESEARCH DATA COLLECTION TOOL
B3: 📌 ABOUT THIS WORKBOOK
B4: Project | C4: Product Packaging Revision & Relaunch — Vanguards Management Trainee Program
B5: Brands Benchmarked | C5: Asian Paints | Birla Opus | Dulux Paints | JSW Paints
B6: Methodology | C6: Semi-Structured Depth Interviews (SSDI) with Key Informants (KIs)
B7: Research Design | C7: Funnel Technique — Broad → Narrow → Specific
B9: 📂 SHEET GUIDE
B10: 🏪 Dealer_Retailer | C10: Record responses from 15–20 dealer/retailer interviews. 15 questions across 5 sections.
B11: 🔨 Contractor | C11: Record responses from 15–20 contractor/painter interviews. 8 questions across 3 sections.
B12: 🏭 Distributor_Wholesaler | C12: Record responses from 5–10 distributor/wholesaler interviews. 5 questions.
B13: 👤 Customer | C13: Record responses from 20–30 end-customer interviews. 5 quick questions.
B14: 📊 Brand_Mention_Freq | C14: Auto-tallies how many times each brand is mentioned per question across all sheets.
B15: 🔢 Sentiment_Coding | C15: Enter sentiment scores (1–10) per respondent per dimension. Auto-averages.
B16: 🏆 Master_Benchmark | C16: Auto-calculated final benchmarking matrix with Indices for all 4 brands.
B18: 🖊️ HOW TO USE — DATA ENTRY
B19: Step 1 | C19: Open the relevant stakeholder sheet (Dealer, Contractor, Distributor, or Customer).
B20: Step 2 | C20: Each row = one respondent. Fill in Name/ID, Location, Date.
B21: Step 3 | C21: During/after interview, type the respondent's answer in the response column.
B22: Step 4 | C22: In the Brand Mentioned column, select which brand(s) they mentioned (dropdown).
B23: Step 5 | C23: After the interview, go to Sentiment_Coding sheet and score that respondent 1–10.
B24: Step 6 | C24: All summary tabs (Brand_Mention_Freq, Master_Benchmark) auto-update via formulas.
B25: Step 7 | C25: Use the Master_Benchmark sheet for final PPT insights and index scores.
B27: 📏 SCORING METHODS USED
B28: Method 1 — Brand Mention Frequency | C28: Counts how many KIs mentioned each brand per question. Score = (Mentions ÷ Max Mentions) × 10
B29: Method 2 — Sentiment Coding | C29: You rate each response 1–10 using the codebook (Best=10, Excellent=9, Very Good=8 ... Very Poor=1).
B30: Method 3 — Ranking Score | C30: If respondent ranked brands, Rank 1 = 5 pts, Rank 2 = 3 pts, Rank 3 = 1 pt. Aggregated.
B31: Final Index Score | C31: Average of Sentiment Score × 0.5 + Mention Frequency Score × 0.3 + Ranking Score × 0.2

Sheet 🏪 Dealer_Retailer
A1: 📋 🏪 DEALER RETAILER — INTERVIEW DATA COLLECTION
A2: INSTRUCTIONS: Fill one row per respondent. Type verbatim responses in Q columns. Select brand mentioned from dropdown. Complete Sentiment_Coding sheet after each interview.
A3: RESPONDENT INFO | F3: SECTION 1: Market Understanding | I3: SECTION 2: Packaging Visibility | L3: SECTION 3: Product Understanding | O3: SECTION 4: Premium Perception | R3: SECTION 5: Recommendation Behavior | U3: CODING & NOTES
A4: D001 | B4: Meera Bose | C4: Chennai | D4: 29-May-2025 | E4: Urban Retail | F4: Asian Paints — especially Royale and Apcolite. Customers already trust it. | G4: Asian Paints is easiest — customers recognise it, less explanation needed. Dulux Paints also easy. | H4: Mid-range | I4: Asian Paints — the red colour stands out immediately even from shop entrance. | J4: Asian Paints — visual block on shelf is very strong. | K4: Mostly Birla Opus gets ignored — poor shelf visibility and unclear packaging. | L4: Asian Paints — clear product names, everyone knows Royale, Ultima, Apcolite hierarchy. | M4: Customers often confuse Birla Opus variants — similar looking packs in same range. | N4: Rarely — customers ask about product type and variant differences. | O4: AP has premium associations built over decades. Pack reflects that heritage. | P4: Asian Paints — customers trust it without even reading the claims. | Q4: Birla Opus looks most modern — clean and contemporary design. | R4: Yes, Asian Paints packaging helps — especially warranty badge and colour chip. Makes customer confident. | S4: Asian Paints is easiest to explain — clear product naming and features. JSW requires more explanation. | T4: More visual differentiation between product grades | U4: Asian Paints | V4: Asian Paints | W4: Strong Asian Paints advocate. Urban Retail dealer. Key insight: Simpler benefit claims — too technical currently
A5: D002 | B5: Vinod Mishra | C5: Nagpur | D5: 03-Mar-2025 | E5: Premium Retail | F5: JSW is new but picking up. Customers who come for AP sometimes notice JSW due to price. | G5: JSW Paints is easiest — customers recognise it, less explanation needed. Dulux Paints also easy. | H5: Premium | I5: Honestly JSW doesn't stand out much on shelf. Gets lost between AP and Opus. | J5: JSW is improving but still lost on shelf between AP and Opus. | K5: Mostly Dulux Paints gets ignored — poor shelf visibility and unclear packaging. | L5: JSW is a bit confusing — customers sometimes pick wrong product. Too many similar packs. | M5: Customers often confuse Birla Opus variants — similar looking packs in same range. | N5: Sometimes — customers ask about product type and variant differences. | O5: JSW looks like economy brand even in premium range. Packaging needs to change. | P5: JSW needs more time to build trust. Still challenger brand. | Q5: Birla Opus looks most modern — clean and contemporary design. | R5: Yes, JSW Paints packaging helps — especially warranty badge and colour chip. Makes customer confident. | S5: JSW Paints is easiest to explain — clear product naming and features. Dulux requires more explanation. | T5: More visual differentiation between product grades | U5: JSW Paints | V5: JSW Paints | W5: Strong JSW Paints advocate. Premium Retail dealer. Key insight: More visual differentiation between product grades
A6: D003 | B6: Bharat Yadav | C6: Chennai | D6: 29-May-2025 | E6: Premium Retail | F6: AP and Birla Opus together. But AP has stronger name recall. | G6: Asian Paints is easiest — customers recognise it, less explanation needed. JSW Paints also easy. | H6: Premium | I6: AP always. Their shelf display is dominant, pack colour is very recognisable. | J6: AP packaging with bold brand name stands out from 5 feet away. | K6: Mostly Birla Opus gets ignored — poor shelf visibility and unclear packaging. | L6: Asian Paints — clear product names, everyone knows Royale, Ultima, Apcolite hierarchy. | M6: Customers often confuse JSW Paints variants — similar looking packs in same range. | N6: Rarely — customers ask about product type and variant differences. | O6: Asian Paints Royale — gold foil, heavy pack, premium feel. Customers associate AP with luxury. | P6: Asian Paints — customers trust it without even reading the claims. | Q6: Birla Opus looks most modern — clean and contemporary design. | R6: Yes, Asian Paints packaging helps — especially warranty badge and colour chip. Makes customer confident. | S6: Asian Paints is easiest to explain — clear product naming and features. JSW requires more explanation. | T6: Clearer hierarchy between premium and standard ranges | U6: Asian Paints | V6: Asian Paints | W6: Strong Asian Paints advocate. Premium Retail dealer. Key insight: More visual differentiation between product grades
A7: D004 | B7: Pooja Menon | C7: Nagpur | D7: 01-May-2025 | E7: Semi-Urban Retail | F7: Asian Paints — especially Royale and Apcolite. Customers already trust it. | G7: Asian Paints is easiest — customers recognise it, less explanation needed. Birla Opus also easy. | H7: Economy | I7: Asian Paints — strong colour block and brand name is large, reads from distance. | J7: Asian Paints — visual block on shelf is very strong. | K7: Mostly JSW Paints gets ignored — poor shelf visibility and unclear packaging. | L7: AP is easiest. The range ladder is very clear — Premium, mid, economy all distinct. | M7: Customers often confuse Birla Opus variants — similar looking packs in same range. | N7: Rarely — customers ask about product type and variant differences. | O7: Asian Paints Royale — gold foil, heavy pack, premium feel. Customers associate AP with luxury. | P7: Asian Paints — customers trust it without even reading the claims. | Q7: Birla Opus looks most modern — clean and contemporary design. | R7: Yes, Asian Paints packaging helps — especially warranty badge and colour chip. Makes customer confident. | S7: Asian Paints is easiest to explain — clear product naming and features. JSW requires more explanation. | T7: Simpler benefit claims — too technical currently | U7: Asian Paints | V7: Asian Paints | W7: Strong Asian Paints advocate. Semi-Urban Retail dealer. Key insight: QR code that shows colour on walls would help selling
A8: D005 | B8: Sanjay Joshi | C8: Delhi | D8: 06-Mar-2025 | E8: Urban Retail | F8: JSW is new but picking up. Customers who come for AP sometimes notice JSW due to price. | G8: JSW Paints is easiest — customers recognise it, less explanation needed. Asian Paints also easy. | H8: Mid-range | I8: JSW is not very visible — pack looks similar to economy range of other brands. | J8: JSW doesn't stand out as much — needs stronger colour identity. | K8: Mostly Dulux Paints gets ignored — poor shelf visibility and unclear packaging. | L8: JSW pack is hard to explain quickly. Claims are technical, customers don't understand. | M8: Customers often confuse Asian Paints variants — similar looking packs in same range. | N8: Sometimes — customers ask about product type and variant differences. | O8: JSW doesn't look premium yet — needs design upgrade. Pack looks functional not aspirational. | P8: JSW needs more time to build trust. Still challenger brand. | Q8: Birla Opus looks most modern — clean and contemporary design. | R8: Yes, JSW Paints packaging helps — especially warranty badge and colour chip. Makes customer confident. | S8: JSW Paints is easiest to explain — clear product naming and features. Dulux requires more explanation. | T8: Pack size printed bigger — hard to tell 1L from 4L quickly | U8: JSW Paints | V8: JSW Paints | W8: Strong JSW Paints advocate. Urban Retail dealer. Key insight: Pack size printed bigger — hard to tell 1L from 4L quickly
A9: D006 | B9: Manoj Joshi | C9: Kolkata | D9: 01-May-2025 | E9: Urban Retail | F9: Birla Opus is growing very fast. Their marketing push is strong right now. | G9: Birla Opus is easiest — customers recognise it, less explanation needed. Asian Paints also easy. | H9: Luxury | I9: Opus — their new packaging is bold. Customers often pick it up first to look. | J9: Opus metallic finish packaging stands out — very premium visual. | K9: Mostly Asian Paints gets ignored — poor shelf visibility and unclear packaging. | L9: Opus is clear for premium customers but economy range confuses some buyers. | M9: Customers often confuse Asian Paints variants — similar looking packs in same range. | N9: Sometimes — customers ask about product type and variant differences. | O9: Birla Opus Velvet Touch — very premium look. Black and gold is instantly luxury. | P9: Opus — Aditya Birla group association gives automatic trust. | Q9: Dulux Paints looks most modern — clean and contemporary design. | R9: Yes, Birla Opus packaging helps — especially warranty badge and colour chip. Makes customer confident. | S9: Birla Opus is easiest to explain — clear product naming and features. JSW requires more explanation. | T9: Clearer hierarchy between premium and standard ranges | U9: Birla Opus | V9: Birla Opus | W9: Strong Birla Opus advocate. Urban Retail dealer. Key insight: Simpler benefit claims — too technical currently
A10: D007 | B10: Dinesh Desai | C10: Bengaluru | D10: 06-May-2025 | E10: Semi-Urban Retail | F10: AP and Birla Opus together. But AP has stronger name recall. | G10: Asian Paints is easiest — customers recognise it, less explanation needed. Dulux Paints also easy. | H10: Economy | I10: AP always. Their shelf display is dominant, pack colour is very recognisable. | J10: AP packaging with bold brand name stands out from 5 feet away. | K10: Mostly JSW Paints gets ignored — poor shelf visibility and unclear packaging. | L10: AP is easiest. The range ladder is very clear — Premium, mid, economy all distinct. | M10: Customers often confuse Dulux Paints variants — similar looking packs in same range. | N10: Rarely — customers ask about product type and variant differences. | O10: Asian Paints Royale — gold foil, heavy pack, premium feel. Customers associate AP with luxury. | P10: AP — decades of brand equity make pack instantly trustworthy. | Q10: Birla Opus looks most modern — clean and contemporary design. | R10: Yes, Asian Paints packaging helps — especially warranty badge and colour chip. Makes customer confident. | S10: Asian Paints is easiest to explain — clear product naming and features. JSW requires more explanation. | T10: Simpler benefit claims — too technical currently | U10: Asian Paints | V10: Asian Paints | W10: Strong Asian Paints advocate. Semi-Urban Retail dealer. Key insight: Simpler benefit claims — too technical currently
A11: D008 | B11: Rajesh Gupta | C11: Pune | D11: 10-May-2025 | E11: Urban Retail | F11: Asian Paints always leads — customers ask for it by name without seeing the pack. | G11: Asian Paints is easiest — customers recognise it, less explanation needed. Birla Opus also easy. | H11: Premium | I11: Asian Paints — the red colour stands out immediately even from shop entrance. | J11: AP packaging with bold brand name stands out from 5 feet away. | K11: Mostly Dulux Paints gets ignored — poor shelf visibility and unclear packaging. | L11: AP is easiest. The range ladder is very clear — Premium, mid, economy all distinct. | M11: Customers often confuse Dulux Paints variants — similar looking packs in same range. | N11: Rarely — customers ask about product type and variant differences. | O11: Asian Paints Royale — gold foil, heavy pack, premium feel. Customers associate AP with luxury. | P11: AP — decades of brand equity make pack instantly trustworthy. | Q11: Birla Opus looks most modern — clean and contemporary design. | R11: Yes, Asian Paints packaging helps — especially warranty badge and colour chip. Makes customer confident. | S11: Asian Paints is easiest to explain — clear product naming and features. JSW requires more explanation. | T11: Better colour coding between interior and exterior products | U11: Asian Paints | V11: Asian Paints | W11: Strong Asian Paints advocate. Urban Retail dealer. Key insight: Better colour coding between interior and exterior products
A12: D009 | B12: Dinesh Joshi | C12: Nagpur | D12: 20-May-2025 | E12: Premium Retail | F12: AP moves fastest, no doubt. Very strong brand pull in premium and mid segment. | G12: Asian Paints is easiest — customers recognise it, less explanation needed. Birla Opus also easy. | H12: Premium | I12: Asian Paints — the red colour stands out immediately even from shop entrance. | J12: Asian Paints — visual block on shelf is very strong. | K12: Mostly Birla Opus gets ignored — poor shelf visibility and unclear packaging. | L12: Asian Paints — clear product names, everyone knows Royale, Ultima, Apcolite hierarchy. | M12: Customers often confuse Dulux Paints variants — similar looking packs in same range. | N12: Rarely — customers ask about product type and variant differences. | O12: Asian Paints Royale — gold foil, heavy pack, premium feel. Customers associate AP with luxury. | P12: AP — decades of brand equity make pack instantly trustworthy. | Q12: Birla Opus looks most modern — clean and contemporary design. | R12: Yes, Asian Paints packaging helps — especially warranty badge and colour chip. Makes customer confident. | S12: Asian Paints is easiest to explain — clear product naming and features. JSW requires more explanation. | T12: Bigger product name — customers can't read from distance | U12: Asian Paints | V12: Asian Paints | W12: Strong Asian Paints advocate. Premium Retail dealer. Key insight: Larger warranty badge on front panel
A13: D010 | B13: Sunil Mishra | C13: Pune | D13: 16-Mar-2025 | E13: Semi-Urban Retail | F13: JSW is slow — customers don't ask for it yet. We push it when margin is better. | G13: JSW Paints is easiest — customers recognise it, less explanation needed. Dulux Paints also easy. | H13: Economy | I13: JSW is not very visible — pack looks similar to economy range of other brands. | J13: JSW is improving but still lost on shelf between AP and Opus. | K13: Mostly Birla Opus gets ignored — poor shelf visibility and unclear packaging. | L13: We have to explain JSW products more — the hierarchy is not obvious from pack. | M13: Customers often confuse Dulux Paints variants — similar looking packs in same range. | N13: Sometimes — customers ask about product type and variant differences. | O13: JSW looks like economy brand even in premium range. Packaging needs to change. | P13: JSW needs more time to build trust. Still challenger brand. | Q13: Birla Opus looks most modern — clean and contemporary design. | R13: Yes, JSW Paints packaging helps — especially warranty badge and colour chip. Makes customer confident. | S13: JSW Paints is easiest to explain — clear product naming and features. Dulux requires more explanation. | T13: Clearer hierarchy between premium and standard ranges | U13: JSW Paints | V13: JSW Paints | W13: Strong JSW Paints advocate. Semi-Urban Retail dealer. Key insight: Application instructions should be clearer on pack
A14: D011 | B14: Ganesh Bose | C14: Mumbai | D14: 02-Apr-2025 | E14: Premium Retail | F14: Asian Paints always leads — customers ask for it by name without seeing the pack. | G14: Asian Paints is easiest — customers recognise it, less explanation needed. JSW Paints also easy. | H14: Luxury | I14: Asian Paints — the red colour stands out immediately even from shop entrance. | J14: Asian Paints — visual block on shelf is very strong. | K14: Mostly JSW Paints gets ignored — poor shelf visibility and unclear packaging. | L14: Asian Paints — clear product names, everyone knows Royale, Ultima, Apcolite hierarchy. | M14: Customers often confuse JSW Paints variants — similar looking packs in same range. | N14: Rarely — customers ask about product type and variant differences. | O14: AP has premium associations built over decades. Pack reflects that heritage. | P14: AP — decades of brand equity make pack instantly trustworthy. | Q14: Birla Opus looks most modern — clean and contemporary design. | R14: Yes, Asian Paints packaging helps — especially warranty badge and colour chip. Makes customer confident. | S14: Asian Paints is easiest to explain — clear product naming and features. JSW requires more explanation. | T14: Larger warranty badge on front panel | U14: Asian Paints | V14: Asian Paints | W14: Strong Asian Paints advocate. Premium Retail dealer. Key insight: Pack size printed bigger — hard to tell 1L from 4L quickly
A15: D012 | B15: Nitin Dubey | C15: Jaipur | D15: 25-Apr-2025 | E15: Premium Retail | F15: AP and Dulux together. Dulux has strong trust especially in Weathershield exterior. | G15: Dulux Paints is easiest — customers recognise it, less explanation needed. Birla Opus also easy. | H15: Luxury | I15: Sometimes Dulux, depends on placement. Their premium range stands out. | J15: Dulux weathershield pack — very strong visual, good shelf presence. | K15: Mostly Birla Opus gets ignored — poor shelf visibility and unclear packaging. | L15: Dulux is clear for exterior products. Weathershield is a strong concept customers get. | M15: Customers often confuse Birla Opus variants — similar looking packs in same range. | N15: Sometimes — customers ask about product type and variant differences. | O15: Dulux — the white and clean minimal design feels international and premium. | P15: Dulux — international brand, customers trust the global standard. | Q15: Birla Opus looks most modern — clean and contemporary design. | R15: Yes, Dulux Paints packaging helps — especially warranty badge and colour chip. Makes customer confident. | S15: Dulux Paints is easiest to explain — clear product naming and features. JSW requires more explanation. | T15: QR code that shows colour on walls would help selling | U15: Dulux Paints | V15: Dulux Paints | W15: Strong Dulux Paints advocate. Premium Retail dealer. Key insight: Eco certifications more visible — customers care about this now
... A33: D030 | B33: Kavita Tiwari | C33: Delhi | D33: 15-Mar-2025 | E33: Urban Retail | F33: JSW is new but picking up. Customers who come for AP sometimes notice JSW due to price. | G33: JSW Paints is easiest — customers recognise it, less explanation needed. Asian Paints also easy. | H33: Economy | I33: Honestly JSW doesn't stand out much on shelf. Gets lost between AP and Opus. | J33: JSW is improving but still lost on shelf between AP and Opus. | K33: Mostly Birla Opus gets ignored — poor shelf visibility and unclear packaging. | L33: JSW pack is hard to explain quickly. Claims are technical, customers don't understand. | M33: Customers often confuse Dulux Paints variants — similar looking packs in same range. | N33: Sometimes — customers ask about product type and variant differences. | O33: JSW looks like economy brand even in premium range. Packaging needs to change. | P33: JSW trust is building — the warranty claim is compelling when explained. | Q33: Birla Opus looks most modern — clean and contemporary design. | R33: Yes, JSW Paints packaging helps — especially warranty badge and colour chip. Makes customer confident. | S33: JSW Paints is easiest to explain — clear product naming and features. Dulux requires more explanation. | T33: Eco certifications more visible — customers care about this now | U33: JSW Paints | V33: JSW Paints | W33: Strong JSW Paints advocate. Urban Retail dealer. Key insight: Clearer hierarchy between premium and standard ranges

Sheet 🔨 Contractor
A1: 📋 🔨 CONTRACTOR — INTERVIEW DATA COLLECTION
A2: INSTRUCTIONS: Fill one row per respondent. Type verbatim responses in Q columns. Select brand mentioned from dropdown. Complete Sentiment_Coding sheet after each interview.
A3: RESPONDENT INFO | F3: SECTION 1: Brand Recognition | I3: SECTION 2: Product Clarity | K3: SECTION 3: Quality & Trust | N3: CODING & NOTES
A4: C001 | B4: Bharat Nair | C4: Delhi | D4: 12-May-2025 | E4: Residential Painter | F4: Opus is easy now — gold and black is very distinct. Good on site. | G4: Birla Opus from distance — colour and label design makes it easy. Good colour block. | H4: Sometimes confuse Asian Paints variants — similar packs in standard range. | I4: AP has clearest interior/exterior differentiation. Birla Opus also good but not perfect. | J4: Birla Opus clearest product naming — range names make sense even on site. | K4: Opus packaging is impressive — premium feel, sturdy construction. | L4: Opus gives confidence especially in premium projects — clients impress. | M4: Opus old packaging before rebrand was very outdated. New one is good. | N4: Birla Opus | O4: Birla Opus | P4: Experienced contractor. Key feedback: QR code that shows colour on walls would help selling
A5: C002 | B5: Arjun Joshi | C5: Delhi | D5: 17-Mar-2025 | E5: Site Contractor | F5: Birla Opus — the new packaging stands out even in poor light on site. | G5: Birla Opus from distance — colour and label design makes it easy. Good colour block. | H5: Sometimes confuse Asian Paints variants — similar packs in standard range. | I5: AP has clearest interior/exterior differentiation. Birla Opus also good but not perfect. | J5: Birla Opus clearest product naming — range names make sense even on site. | K5: Opus packaging is impressive — premium feel, sturdy construction. | L5: Opus gives confidence especially in premium projects — clients impress. | M5: Opus old packaging before rebrand was very outdated. New one is good. | N5: Birla Opus | O5: Birla Opus | P5: Experienced contractor. Key feedback: Bigger product name — customers can't read from distance
A6: C003 | B6: Rajesh Dubey | C6: Chennai | D6: 03-Mar-2025 | E6: Independent Applicator | F6: AP — the red bucket is unmistakeable from across the room. Never confuse it. | G6: Asian Paints from distance — colour and label design makes it easy. Good colour block. | H6: Sometimes confuse Dulux Paints variants — similar packs in standard range. | I6: Opus has clearest interior/exterior differentiation. Asian Paints also good but not perfect. | J6: Asian Paints clearest product naming — range names make sense even on site. | K6: AP looks high quality — heavy label, good print, reliable lid. | L6: AP always gives confidence — proven product inside, consistent every time. | M6: AP Apcolite standard range looks old-fashioned now. | N6: Asian Paints | O6: Asian Paints | P6: Experienced contractor. Key feedback: More visual differentiation between product grades
A7: C004 | B7: Vikram Tiwari | C7: Kolkata | D7: 16-Apr-2025 | E7: Residential Painter | F7: Dulux — the blue and white is clean, easy to read. Pick it up fast. | G7: Dulux Paints from distance — colour and label design makes it easy. Good colour block. | H7: Sometimes confuse Birla Opus variants — similar packs in standard range. | I7: AP has clearest interior/exterior differentiation. Dulux Paints also good but not perfect. | J7: Dulux Paints clearest product naming — range names make sense even on site. | K7: Dulux looks professional — clean, international quality feel. | L7: Dulux exterior pack gives confidence for weather protection claims. | M7: Dulux could modernise — feels like 2010s design language currently. | N7: Dulux Paints | O7: Dulux Paints | P7: Experienced contractor. Key feedback: Pack size printed bigger — hard to tell 1L from 4L quickly
A8: C005 | B8: Manoj Tiwari | C8: Ahmedabad | D8: 24-Apr-2025 | E8: Residential Painter | F8: JSW we sometimes confuse with other brands. Pack looks a bit similar to cheaper brands. | G8: JSW Paints from distance — colour and label design makes it easy. Good colour block. | H8: Sometimes confuse Birla Opus variants — similar packs in standard range. | I8: AP has clearest interior/exterior differentiation. JSW Paints also good but not perfect. | J8: JSW Paints clearest product naming — range names make sense even on site. | K8: JSW quality looks acceptable but label sometimes unclear after handling. | L8: JSW I need to explain more to clients — pack doesn't speak for itself yet. | M8: JSW looks most outdated compared to Opus and AP premium range. | N8: JSW Paints | O8: JSW Paints | P8: Experienced contractor. Key feedback: QR code that shows colour on walls would help selling
A9: C006 | B9: Ravi Kumar | C9: Delhi | D9: 05-Apr-2025 | E9: Waterproofing Contractor | F9: JSW takes more time to identify. We read the label carefully to confirm. | G9: JSW Paints from distance — colour and label design makes it easy. Good colour block. | H9: Sometimes confuse Birla Opus variants — similar packs in standard range. | I9: AP has clearest interior/exterior differentiation. JSW Paints also good but not perfect. | J9: JSW Paints clearest product naming — range names make sense even on site. | K9: JSW quality looks acceptable but label sometimes unclear after handling. | L9: JSW sometimes client questions when they see pack — needs stronger trust signals. | M9: JSW needs urgent packaging update — looks behind competitors. | N9: JSW Paints | O9: JSW Paints | P9: Experienced contractor. Key feedback: Clearer hierarchy between premium and standard ranges
A10: C007 | B10: Pooja Rao | C10: Kolkata | D10: 30-Mar-2025 | E10: Residential Painter | F10: JSW takes more time to identify. We read the label carefully to confirm. | G10: JSW Paints from distance — colour and label design makes it easy. Good colour block. | H10: Sometimes confuse Birla Opus variants — similar packs in standard range. | I10: AP has clearest interior/exterior differentiation. JSW Paints also good but not perfect. | J10: JSW Paints clearest product naming — range names make sense even on site. | K10: JSW quality looks acceptable but label sometimes unclear after handling. | L10: JSW sometimes client questions when they see pack — needs stronger trust signals. | M10: JSW needs urgent packaging update — looks behind competitors. | N10: JSW Paints | O10: JSW Paints | P10: Experienced contractor. Key feedback: Clearer hierarchy between premium and standard ranges
A11: C008 | B11: Mohan Shah | C11: Lucknow | D11: 02-Apr-2025 | E11: Independent Applicator | F11: JSW takes more time to identify. We read the label carefully to confirm. | G11: JSW Paints from distance — colour and label design makes it easy. Good colour block. | H11: Sometimes confuse Asian Paints variants — similar packs in standard range. | I11: AP has clearest interior/exterior differentiation. JSW Paints also good but not perfect. | J11: JSW Paints clearest product naming — range names make sense even on site. | K11: JSW quality looks acceptable but label sometimes unclear after handling. | L11: JSW I need to explain more to clients — pack doesn't speak for itself yet. | M11: JSW looks most outdated compared to Opus and AP premium range. | N11: JSW Paints | O11: JSW Paints | P11: Experienced contractor. Key feedback: Clearer hierarchy between premium and standard ranges
A12: C009 | B12: Mohan Singh | C12: Nagpur | D12: 17-Apr-2025 | E12: Residential Painter | F12: Dulux — the blue and white is clean, easy to read. Pick it up fast. | G12: Dulux Paints from distance — colour and label design makes it easy. Good colour block. | H12: Sometimes confuse JSW Paints variants — similar packs in standard range. | I12: AP has clearest interior/exterior differentiation. Dulux Paints also good but not perfect. | J12: Dulux Paints clearest product naming — range names make sense even on site. | K12: Dulux looks professional — clean, international quality feel. | L12: Dulux Weathershield — pack design reinforces the product promise. | M12: Dulux standard range feels a bit traditional — not cutting edge design. | N12: Dulux Paints | O12: Dulux Paints | P12: Experienced contractor. Key feedback: Eco certifications more visible — customers care about this now
A13: C010 | B13: Mohan Menon | C13: Mumbai | D13: 06-Apr-2025 | E13: Independent Applicator | F13: Asian Paints always. On site we pick it up instantly, no reading needed. | G13: Asian Paints from distance — colour and label design makes it easy. Good colour block. | H13: Sometimes confuse Dulux Paints variants — similar packs in standard range. | I13: Opus has clearest interior/exterior differentiation. Asian Paints also good but not perfect. | J13: Asian Paints clearest product naming — range names make sense even on site. | K13: AP looks high quality — heavy label, good print, reliable lid. | L13: AP always gives confidence — proven product inside, consistent every time. | M13: Some of AP economy range looks dated — not premium enough. | N13: Asian Paints | O13: Asian Paints | P13: Experienced contractor. Key feedback: Pack size printed bigger — hard to tell 1L from 4L quickly
A14: C011 | B14: Deepak Yadav | C14: Jaipur | D14: 17-Apr-2025 | E14: Site Contractor | F14: JSW we sometimes confuse with other brands. Pack looks a bit similar to cheaper brands. | G14: JSW Paints from distance — colour and label design makes it easy. Good colour block. | H14: Sometimes confuse Birla Opus variants — similar packs in standard range. | I14: AP has clearest interior/exterior differentiation. JSW Paints also good but not perfect. | J14: JSW Paints clearest product naming — range names make sense even on site. | K14: JSW pack is decent — but not as premium as AP or Opus yet. | L14: JSW sometimes client questions when they see pack — needs stronger trust signals. | M14: JSW looks most outdated compared to Opus and AP premium range. | N14: JSW Paints | O14: JSW Paints | P14: Experienced contractor. Key feedback: Application instructions should be clearer on pack
A15: C012 | B15: Rahul Gupta | C15: Pune | D15: 29-May-2025 | E15: Independent Applicator | F15: Asian Paints always. On site we pick it up instantly, no reading needed. | G15: Asian Paints from distance — colour and label design makes it easy. Good colour block. | H15: Sometimes confuse Dulux Paints variants — similar packs in standard range. | I15: Opus has clearest interior/exterior differentiation. Asian Paints also good but not perfect. | J15: Asian Paints clearest product naming — range names make sense even on site. | K15: Asian Paints — pack material is solid, label stays on during work. | L15: AP always gives confidence — proven product inside, consistent every time. | M15: Some of AP economy range looks dated — not premium enough. | N15: Asian Paints | O15: Asian Paints | P15: Experienced contractor. Key feedback: Larger warranty badge on front panel
... A33: C030 | B33: Tarun Mehta | C33: Pune | D33: 24-May-2025 | E33: Waterproofing Contractor | F33: JSW we sometimes confuse with other brands. Pack looks a bit similar to cheaper brands. | G33: JSW Paints from distance — colour and label design makes it easy. Good colour block. | H33: Sometimes confuse Birla Opus variants — similar packs in standard range. | I33: AP has clearest interior/exterior differentiation. JSW Paints also good but not perfect. | J33: JSW Paints clearest product naming — range names make sense even on site. | K33: JSW pack is decent — but not as premium as AP or Opus yet. | L33: JSW I need to explain more to clients — pack doesn't speak for itself yet. | M33: JSW needs urgent packaging update — looks behind competitors. | N33: JSW Paints | O33: JSW Paints | P33: Experienced contractor. Key feedback: Better colour coding between interior and exterior products

Sheet 🏭 Distributor_Wholesaler
A1: 📋 🏭 DISTRIBUTOR WHOLESALER — INTERVIEW DATA COLLECTION
A2: INSTRUCTIONS: Fill one row per respondent. Type verbatim responses in Q columns. Select brand mentioned from dropdown. Complete Sentiment_Coding sheet after each interview.
A3: RESPONDENT INFO | F3: SKU ARCHITECTURE | I3: WAREHOUSE OPS | J3: VISUAL CONSISTENCY | K3: CODING & NOTES
A4: DW001 | B4: Nandini Sharma | C4: Chennai | D4: 09-Apr-2025 | E4: Sub-Distributor | F4: Birla Opus is well organised — premium, mid, economy all clearly differentiated. | G4: Birla Opus clearest SKU differentiation — colour coding and naming are consistent. | H4: JSW creates most confusion — similar pack colours in different ranges. | I4: Birla Opus easiest in warehouse — strong colour identity and clear size marking on pack. | J4: Asian Paints has strongest visual consistency. Birla Opus improving. | K4: Birla Opus | L4: Birla Opus | M4: Distributor insight: Simpler benefit claims — too technical currently
A5: DW002 | B5: Vinod Reddy | C5: Hyderabad | D5: 18-Mar-2025 | E5: C&F Agent | F5: AP is best organised — clear range hierarchy, consistent visual across all SKUs. | G5: Asian Paints clearest SKU differentiation — colour coding and naming are consistent. | H5: JSW creates most confusion — similar pack colours in different ranges. | I5: Asian Paints easiest in warehouse — strong colour identity and clear size marking on pack. | J5: Birla Opus has strongest visual consistency. Asian Paints improving. | K5: Asian Paints | L5: Asian Paints | M5: Distributor insight: Clearer hierarchy between premium and standard ranges
A6: DW003 | B6: Deepak Sinha | C6: Jaipur | D6: 07-May-2025 | E6: C&F Agent | F6: JSW has work to do — similar looking packs in warehouse cause picking errors. | G6: JSW Paints clearest SKU differentiation — colour coding and naming are consistent. | H6: Dulux creates most confusion — similar pack colours in different ranges. | I6: JSW Paints easiest in warehouse — strong colour identity and clear size marking on pack. | J6: Asian Paints has strongest visual consistency. JSW Paints improving. | K6: JSW Paints | L6: JSW Paints | M6: Distributor insight: QR code that shows colour on walls would help selling
A7: DW004 | B7: Tarun Verma | C7: Delhi | D7: 24-Mar-2025 | E7: Regional Wholesaler | F7: Dulux is consistent — same visual language across interior, exterior, wood range. | G7: Dulux Paints clearest SKU differentiation — colour coding and naming are consistent. | H7: JSW creates most confusion — similar pack colours in different ranges. | I7: Dulux Paints easiest in warehouse — strong colour identity and clear size marking on pack. | J7: Asian Paints has strongest visual consistency. Dulux Paints improving. | K7: Dulux Paints | L7: Dulux Paints | M7: Distributor insight: Pack size printed bigger — hard to tell 1L from 4L quickly
A8: DW005 | B8: Laxmi Yadav | C8: Lucknow | D8: 31-Mar-2025 | E8: Metro Distributor | F8: JSW organisation is weakest — need clearer differentiation especially primer vs putty. | G8: JSW Paints clearest SKU differentiation — colour coding and naming are consistent. | H8: Dulux creates most confusion — similar pack colours in different ranges. | I8: JSW Paints easiest in warehouse — strong colour identity and clear size marking on pack. | J8: Asian Paints has strongest visual consistency. JSW Paints improving. | K8: JSW Paints | L8: JSW Paints | M8: Distributor insight: Application instructions should be clearer on pack
A9: DW006 | B9: Sunita Nair | C9: Jaipur | D9: 31-Mar-2025 | E9: C&F Agent | F9: Asian Paints portfolio is very well structured. Warehouse staff can identify quickly. | G9: Asian Paints clearest SKU differentiation — colour coding and naming are consistent. | H9: JSW creates most confusion — similar pack colours in different ranges. | I9: Asian Paints easiest in warehouse — strong colour identity and clear size marking on pack. | J9: Birla Opus has strongest visual consistency. Asian Paints improving. | K9: Asian Paints | L9: Asian Paints | M9: Distributor insight: Pack size printed bigger — hard to tell 1L from 4L quickly
A10: DW007 | B10: Nandini Das | C10: Surat | D10: 26-Apr-2025 | E10: Regional Wholesaler | F10: Opus SKU architecture is strong — new pack design made warehouse handling much easier. | G10: Birla Opus clearest SKU differentiation — colour coding and naming are consistent. | H10: JSW creates most confusion — similar pack colours in different ranges. | I10: Birla Opus easiest in warehouse — strong colour identity and clear size marking on pack. | J10: Asian Paints has strongest visual consistency. Birla Opus improving. | K10: Birla Opus | L10: Birla Opus | M10: Distributor insight: Better colour coding between interior and exterior products
A11: DW008 | B11: Laxmi Gupta | C11: Hyderabad | D11: 17-May-2025 | E11: Sub-Distributor | F11: AP is best organised — clear range hierarchy, consistent visual across all SKUs. | G11: Asian Paints clearest SKU differentiation — colour coding and naming are consistent. | H11: JSW creates most confusion — similar pack colours in different ranges. | I11: Asian Paints easiest in warehouse — strong colour identity and clear size marking on pack. | J11: Birla Opus has strongest visual consistency. Asian Paints improving. | K11: Asian Paints | L11: Asian Paints | M11: Distributor insight: Better colour coding between interior and exterior products
A12: DW009 | B12: Geeta Yadav | C12: Jaipur | D12: 14-Mar-2025 | E12: Metro Distributor | F12: AP is best organised — clear range hierarchy, consistent visual across all SKUs. | G12: Asian Paints clearest SKU differentiation — colour coding and naming are consistent. | H12: JSW creates most confusion — similar pack colours in different ranges. | I12: Asian Paints easiest in warehouse — strong colour identity and clear size marking on pack. | J12: Birla Opus has strongest visual consistency. Asian Paints improving. | K12: Asian Paints | L12: Asian Paints | M12: Distributor insight: Better colour coding between interior and exterior products
A13: DW010 | B13: Kiran Joshi | C13: Kolkata | D13: 05-May-2025 | E13: Metro Distributor | F13: Dulux is consistent — same visual language across interior, exterior, wood range. | G13: Dulux Paints clearest SKU differentiation — colour coding and naming are consistent. | H13: JSW creates most confusion — similar pack colours in different ranges. | I13: Dulux Paints easiest in warehouse — strong colour identity and clear size marking on pack. | J13: Asian Paints has strongest visual consistency. Dulux Paints improving. | K13: Dulux Paints | L13: Dulux Paints | M13: Distributor insight: Eco certifications more visible — customers care about this now
A14: DW011 | B14: Dinesh Mishra | C14: Chennai | D14: 04-Mar-2025 | E14: Metro Distributor | F14: Asian Paints portfolio is very well structured. Warehouse staff can identify quickly. | G14: Asian Paints clearest SKU differentiation — colour coding and naming are consistent. | H14: JSW creates most confusion — similar pack colours in different ranges. | I14: Asian Paints easiest in warehouse — strong colour identity and clear size marking on pack. | J14: Birla Opus has strongest visual consistency. Asian Paints improving. | K14: Asian Paints | L14: Asian Paints | M14: Distributor insight: Bigger product name — customers can't read from distance
A15: DW012 | B15: Nandini Nair | C15: Ahmedabad | D15: 11-Mar-2025 | E15: Sub-Distributor | F15: Opus SKU architecture is strong — new pack design made warehouse handling much easier. | G15: Birla Opus clearest SKU differentiation — colour coding and naming are consistent. | H15: JSW creates most confusion — similar pack colours in different ranges. | I15: Birla Opus easiest in warehouse — strong colour identity and clear size marking on pack. | J15: Asian Paints has strongest visual consistency. Birla Opus improving. | K15: Birla Opus | L15: Birla Opus | M15: Distributor insight: Simpler benefit claims — too technical currently
... A18: DW015 | B18: Arjun Kumar | C18: Mumbai | D18: 02-Apr-2025 | E18: Sub-Distributor | F18: Dulux is consistent — same visual language across interior, exterior, wood range. | G18: Dulux Paints clearest SKU differentiation — colour coding and naming are consistent. | H18: JSW creates most confusion — similar pack colours in different ranges. | I18: Dulux Paints easiest in warehouse — strong colour identity and clear size marking on pack. | J18: Asian Paints has strongest visual consistency. Dulux Paints improving. | K18: Dulux Paints | L18: Dulux Paints | M18: Distributor insight: Larger warranty badge on front panel

Sheet 👤 Customer
A1: 📋 👤 CUSTOMER — INTERVIEW DATA COLLECTION
A2: INSTRUCTIONS: Fill one row per respondent. Type verbatim responses in Q columns. Select brand mentioned from dropdown. Complete Sentiment_Coding sheet after each interview.
A3: RESPONDENT INFO | F3: CUSTOMER PERCEPTION | J3: PURCHASE INTENT | K3: CODING & NOTES
A4: CU001 | B4: Rahul Iyer | C4: Kolkata | D4: 06-Mar-2025 | E4: Urban Homeowner | F4: Asian Paints — the pack looks trustworthy and well-designed. | G4: AP looks most premium to me — it's the brand I see everywhere in good homes. | H4: Asian Paints — long track record and I see it in good quality homes. | I4: Dulux Paints is easiest — product names make sense without technical knowledge. | J4: AP — I've seen it in every good home I know. Natural first choice. | K4: Asian Paints | L4: Asian Paints | M4: Customer segment: Urban Homeowner. Paint decision maker: self.
A5: CU002 | B5: Vikram Yadav | C5: Hyderabad | D5: 24-May-2025 | E5: First-time Buyer | F5: Dulux — clean white and blue looks fresh and reliable. Like a hospital brand almost. | G5: Dulux — minimal, clean, international. Feels premium without being loud. | H5: Dulux — international brand. Global quality standard. | I5: Asian Paints is easiest — product names make sense without technical knowledge. | J5: Dulux — for exterior I trust Weathershield most. Good track record. | K5: Dulux Paints | L5: Dulux Paints | M5: Customer segment: First-time Buyer. Paint decision maker: contractor-influenced.
A6: CU003 | B6: Nitin Desai | C6: Lucknow | D6: 29-Apr-2025 | E6: First-time Buyer | F6: Dulux — clean white and blue looks fresh and reliable. Like a hospital brand almost. | G6: Dulux — minimal, clean, international. Feels premium without being loud. | H6: Dulux — international brand. Global quality standard. | I6: Asian Paints is easiest — product names make sense without technical knowledge. | J6: Dulux — for exterior I trust Weathershield most. Good track record. | K6: Dulux Paints | L6: Dulux Paints | M6: Customer segment: First-time Buyer. Paint decision maker: self.
A7: CU004 | B7: Suresh Mehta | C7: Hyderabad | D7: 06-Mar-2025 | E7: Renovation Buyer | F7: Asian Paints catches my eye first — the red colour is very striking on shelf. | G7: Asian Paints Royale — the gold and royal packaging screams premium. | H7: Asian Paints — long track record and I see it in good quality homes. | I7: Dulux Paints is easiest — product names make sense without technical knowledge. | J7: AP — I've seen it in every good home I know. Natural first choice. | K7: Asian Paints | L7: Asian Paints | M7: Customer segment: Renovation Buyer. Paint decision maker: self.
A8: CU005 | B8: Geeta Joshi | C8: Mumbai | D8: 22-May-2025 | E8: Luxury Segment | F8: I didn't notice JSW much — it doesn't stand out as much as AP or Opus. | G8: Honestly not JSW — it looks more mid-range to me currently. | H8: JSW I don't know well enough yet. Need more brand presence. | I8: Asian Paints is easiest — product names make sense without technical knowledge. | J8: JSW if price is better — Any Colour One Price is a good concept for me. | K8: JSW Paints | L8: JSW Paints | M8: Customer segment: Luxury Segment. Paint decision maker: self.
A9: CU006 | B9: Meera Singh | C9: Chennai | D9: 25-Apr-2025 | E9: First-time Buyer | F9: Dulux — clean white and blue looks fresh and reliable. Like a hospital brand almost. | G9: Dulux — minimal, clean, international. Feels premium without being loud. | H9: Dulux feels trustworthy — clean design, clear claims, no gimmicks. | I9: Asian Paints is easiest — product names make sense without technical knowledge. | J9: Dulux for international quality feeling. The packaging is clean and trustworthy. | K9: Dulux Paints | L9: Dulux Paints | M9: Customer segment: First-time Buyer. Paint decision maker: self.
A10: CU007 | B10: Vinod Yadav | C10: Jaipur | D10: 04-Apr-2025 | E10: Renovation Buyer | F10: Birla Opus — the gold packaging is very premium looking. Feels expensive. | G10: Birla Opus looks the most expensive and modern of all of them. | H10: Opus — Aditya Birla brand. That gives automatic trust for me. | I10: Asian Paints is easiest — product names make sense without technical knowledge. | J10: Birla Opus for the living room — it looks most premium for my budget. | K10: Birla Opus | L10: Birla Opus | M10: Customer segment: Renovation Buyer. Paint decision maker: self.
A11: CU008 | B11: Nitin Pandey | C11: Pune | D11: 11-Apr-2025 | E11: Luxury Segment | F11: Dulux — clean white and blue looks fresh and reliable. Like a hospital brand almost. | G11: Dulux — minimal, clean, international. Feels premium without being loud. | H11: Dulux feels trustworthy — clean design, clear claims, no gimmicks. | I11: Asian Paints is easiest — product names make sense without technical knowledge. | J11: Dulux for international quality feeling. The packaging is clean and trustworthy. | K11: Dulux Paints | L11: Dulux Paints | M11: Customer segment: Luxury Segment. Paint decision maker: contractor-influenced.
A12: CU009 | B12: Mohan Gupta | C12: Nagpur | D12: 26-Apr-2025 | E12: Contractor Client | F12: AP — I always notice it first. Strong presence, familiar brand. | G12: AP looks most premium to me — it's the brand I see everywhere in good homes. | H12: AP — it's in my parents' house, it's everywhere. Just trusted. | I12: Dulux Paints is easiest — product names make sense without technical knowledge. | J12: AP — I've seen it in every good home I know. Natural first choice. | K12: Asian Paints | L12: Asian Paints | M12: Customer segment: Contractor Client. Paint decision maker: self.
A13: CU010 | B13: Meera Chatterjee | C13: Mumbai | D13: 10-Mar-2025 | E13: Renovation Buyer | F13: JSW looks okay but I needed to read it to know what it was. | G13: Honestly not JSW — it looks more mid-range to me currently. | H13: JSW is decent but not instantly trusted — I'd want recommendation first. | I13: Asian Paints is easiest — product names make sense without technical knowledge. | J13: JSW if price is better — Any Colour One Price is a good concept for me. | K13: JSW Paints | L13: JSW Paints | M13: Customer segment: Renovation Buyer. Paint decision maker: contractor-influenced.
A14: CU011 | B14: Sunita Patel | C14: Delhi | D14: 09-Mar-2025 | E14: Contractor Client | F14: I didn't notice JSW much — it doesn't stand out as much as AP or Opus. | G14: Honestly not JSW — it looks more mid-range to me currently. | H14: JSW I don't know well enough yet. Need more brand presence. | I14: Asian Paints is easiest — product names make sense without technical knowledge. | J14: JSW because of the unique price point and if contractor recommends it. | K14: JSW Paints | L14: JSW Paints | M14: Customer segment: Contractor Client. Paint decision maker: self.
A15: CU012 | B15: Ravi Das | C15: Kolkata | D15: 17-Apr-2025 | E15: Urban Homeowner | F15: AP — I always notice it first. Strong presence, familiar brand. | G15: AP looks most premium to me — it's the brand I see everywhere in good homes. | H15: AP — it's in my parents' house, it's everywhere. Just trusted. | I15: Dulux Paints is easiest — product names make sense without technical knowledge. | J15: I'd choose Asian Paints — brand trust, good colours, proven quality. | K15: Asian Paints | L15: Asian Paints | M15: Customer segment: Urban Homeowner. Paint decision maker: self.
... A38: CU035 | B38: Ramesh Sinha | C38: Mumbai | D38: 06-Mar-2025 | E38: Contractor Client | F38: I didn't notice JSW much — it doesn't stand out as much as AP or Opus. | G38: Honestly not JSW — it looks more mid-range to me currently. | H38: JSW I don't know well enough yet. Need more brand presence. | I38: Asian Paints is easiest — product names make sense without technical knowledge. | J38: JSW because of the unique price point and if contractor recommends it. | K38: JSW Paints | L38: JSW Paints | M38: Customer segment: Contractor Client. Paint decision maker: self.

Sheet 📊 Brand_Mention_Freq
A1: 📊 BRAND MENTION FREQUENCY TRACKER — Auto-tallied from all interview sheets
A2: This sheet auto-counts how many respondents mentioned each brand per dimension. COUNTIF formulas pull from Brand Mentioned columns in each interview sheet.
A3: Dimension / Question Theme | B3: Asian Paints Mentions | C3: Birla Opus Mentions | D3: Dulux Paints Mentions | E3: JSW Paints Mentions | F3: Total Mentions | G3: AP Score (/10) | H3: BO Score (/10) | I3: DP Score (/10) | J3: JSW Score (/10) | K3: Top Brand | L3: Notes
A4: Fastest Moving / Easiest to Recommend | B4: =COUNTIF('🏪 Dealer_Retailer'!V4:V33,"Asian Paints") -> 12 | C4: =COUNTIF('🏪 Dealer_Retailer'!V4:V33,"Birla Opus") -> 6 | D4: =COUNTIF('🏪 Dealer_Retailer'!V4:V33,"Dulux Paints") -> 5 | E4: =COUNTIF('🏪 Dealer_Retailer'!V4:V33,"JSW Paints") -> 7 | F4: =B4+C4+D4+E4 -> 30 | G4: =IFERROR(ROUND(B4/MAX(B4:E4)*10,1),0) -> 10 | H4: =IFERROR(ROUND(C4/MAX(B4:E4)*10,1),0) -> 5 | I4: =IFERROR(ROUND(D4/MAX(B4:E4)*10,1),0) -> 4.2 | J4: =IFERROR(ROUND(E4/MAX(B4:E4)*10,1),0) -> 5.8 | K4: =IFERROR(INDEX({"Asian Paints","Birla Opus","Dulux Paints","JSW Paints"},MATCH(MAX(B4:E4),B4:E4,0)),"-") -> Asian Paints
A5: First Noticed on Shelf (Visibility) | B5: =COUNTIF('🏪 Dealer_Retailer'!V4:V33,"Asian Paints") -> 12 | C5: =COUNTIF('🏪 Dealer_Retailer'!V4:V33,"Birla Opus") -> 6 | D5: =COUNTIF('🏪 Dealer_Retailer'!V4:V33,"Dulux Paints") -> 5 | E5: =COUNTIF('🏪 Dealer_Retailer'!V4:V33,"JSW Paints") -> 7 | F5: =B5+C5+D5+E5 -> 30 | G5: =IFERROR(ROUND(B5/MAX(B5:E5)*10,1),0) -> 10 | H5: =IFERROR(ROUND(C5/MAX(B5:E5)*10,1),0) -> 5 | I5: =IFERROR(ROUND(D5/MAX(B5:E5)*10,1),0) -> 4.2 | J5: =IFERROR(ROUND(E5/MAX(B5:E5)*10,1),0) -> 5.8 | K5: =IFERROR(INDEX({"Asian Paints","Birla Opus","Dulux Paints","JSW Paints"},MATCH(MAX(B5:E5),B5:E5,0)),"-") -> Asian Paints
A6: Most Premium Looking | B6: =COUNTIF('🏪 Dealer_Retailer'!V4:V33,"Asian Paints") -> 12 | C6: =COUNTIF('🏪 Dealer_Retailer'!V4:V33,"Birla Opus") -> 6 | D6: =COUNTIF('🏪 Dealer_Retailer'!V4:V33,"Dulux Paints") -> 5 | E6: =COUNTIF('🏪 Dealer_Retailer'!V4:V33,"JSW Paints") -> 7 | F6: =B6+C6+D6+E6 -> 30 | G6: =IFERROR(ROUND(B6/MAX(B6:E6)*10,1),0) -> 10 | H6: =IFERROR(ROUND(C6/MAX(B6:E6)*10,1),0) -> 5 | I6: =IFERROR(ROUND(D6/MAX(B6:E6)*10,1),0) -> 4.2 | J6: =IFERROR(ROUND(E6/MAX(B6:E6)*10,1),0) -> 5.8 | K6: =IFERROR(INDEX({"Asian Paints","Birla Opus","Dulux Paints","JSW Paints"},MATCH(MAX(B6:E6),B6:E6,0)),"-") -> Asian Paints
A7: Highest Trust | B7: =COUNTIF('🏪 Dealer_Retailer'!V4:V33,"Asian Paints") -> 12 | C7: =COUNTIF('🏪 Dealer_Retailer'!V4:V33,"Birla Opus") -> 6 | D7: =COUNTIF('🏪 Dealer_Retailer'!V4:V33,"Dulux Paints") -> 5 | E7: =COUNTIF('🏪 Dealer_Retailer'!V4:V33,"JSW Paints") -> 7 | F7: =B7+C7+D7+E7 -> 30 | G7: =IFERROR(ROUND(B7/MAX(B7:E7)*10,1),0) -> 10 | H7: =IFERROR(ROUND(C7/MAX(B7:E7)*10,1),0) -> 5 | I7: =IFERROR(ROUND(D7/MAX(B7:E7)*10,1),0) -> 4.2 | J7: =IFERROR(ROUND(E7/MAX(B7:E7)*10,1),0) -> 5.8 | K7: =IFERROR(INDEX({"Asian Paints","Birla Opus","Dulux Paints","JSW Paints"},MATCH(MAX(B7:E7),B7:E7,0)),"-") -> Asian Paints
A8: Easiest to Understand | B8: =COUNTIF('🏪 Dealer_Retailer'!V4:V33,"Asian Paints") -> 12 | C8: =COUNTIF('🏪 Dealer_Retailer'!V4:V33,"Birla Opus") -> 6 | D8: =COUNTIF('🏪 Dealer_Retailer'!V4:V33,"Dulux Paints") -> 5 | E8: =COUNTIF('🏪 Dealer_Retailer'!V4:V33,"JSW Paints") -> 7 | F8: =B8+C8+D8+E8 -> 30 | G8: =IFERROR(ROUND(B8/MAX(B8:E8)*10,1),0) -> 10 | H8: =IFERROR(ROUND(C8/MAX(B8:E8)*10,1),0) -> 5 | I8: =IFERROR(ROUND(D8/MAX(B8:E8)*10,1),0) -> 4.2 | J8: =IFERROR(ROUND(E8/MAX(B8:E8)*10,1),0) -> 5.8 | K8: =IFERROR(INDEX({"Asian Paints","Birla Opus","Dulux Paints","JSW Paints"},MATCH(MAX(B8:E8),B8:E8,0)),"-") -> Asian Paints
A9: Most Modern | B9: =COUNTIF('🏪 Dealer_Retailer'!V4:V33,"Asian Paints") -> 12 | C9: =COUNTIF('🏪 Dealer_Retailer'!V4:V33,"Birla Opus") -> 6 | D9: =COUNTIF('🏪 Dealer_Retailer'!V4:V33,"Dulux Paints") -> 5 | E9: =COUNTIF('🏪 Dealer_Retailer'!V4:V33,"JSW Paints") -> 7 | F9: =B9+C9+D9+E9 -> 30 | G9: =IFERROR(ROUND(B9/MAX(B9:E9)*10,1),0) -> 10 | H9: =IFERROR(ROUND(C9/MAX(B9:E9)*10,1),0) -> 5 | I9: =IFERROR(ROUND(D9/MAX(B9:E9)*10,1),0) -> 4.2 | J9: =IFERROR(ROUND(E9/MAX(B9:E9)*10,1),0) -> 5.8 | K9: =IFERROR(INDEX({"Asian Paints","Birla Opus","Dulux Paints","JSW Paints"},MATCH(MAX(B9:E9),B9:E9,0)),"-") -> Asian Paints
A10: Recommended by Dealer | B10: =COUNTIF('🏪 Dealer_Retailer'!V4:V33,"Asian Paints") -> 12 | C10: =COUNTIF('🏪 Dealer_Retailer'!V4:V33,"Birla Opus") -> 6 | D10: =COUNTIF('🏪 Dealer_Retailer'!V4:V33,"Dulux Paints") -> 5 | E10: =COUNTIF('🏪 Dealer_Retailer'!V4:V33,"JSW Paints") -> 7 | F10: =B10+C10+D10+E10 -> 30 | G10: =IFERROR(ROUND(B10/MAX(B10:E10)*10,1),0) -> 10 | H10: =IFERROR(ROUND(C10/MAX(B10:E10)*10,1),0) -> 5 | I10: =IFERROR(ROUND(D10/MAX(B10:E10)*10,1),0) -> 4.2 | J10: =IFERROR(ROUND(E10/MAX(B10:E10)*10,1),0) -> 5.8 | K10: =IFERROR(INDEX({"Asian Paints","Birla Opus","Dulux Paints","JSW Paints"},MATCH(MAX(B10:E10),B10:E10,0)),"-") -> Asian Paints
A11: Fastest Contractor Recognition | B11: =COUNTIF('🔨 Contractor'!O4:O33,"Asian Paints") -> 9 | C11: =COUNTIF('🔨 Contractor'!O4:O33,"Birla Opus") -> 6 | D11: =COUNTIF('🔨 Contractor'!O4:O33,"Dulux Paints") -> 5 | E11: =COUNTIF('🔨 Contractor'!O4:O33,"JSW Paints") -> 10 | F11: =B11+C11+D11+E11 -> 30 | G11: =IFERROR(ROUND(B11/MAX(B11:E11)*10,1),0) -> 9 | H11: =IFERROR(ROUND(C11/MAX(B11:E11)*10,1),0) -> 6 | I11: =IFERROR(ROUND(D11/MAX(B11:E11)*10,1),0) -> 5 | J11: =IFERROR(ROUND(E11/MAX(B11:E11)*10,1),0) -> 10 | K11: =IFERROR(INDEX({"Asian Paints","Birla Opus","Dulux Paints","JSW Paints"},MATCH(MAX(B11:E11),B11:E11,0)),"-") -> JSW Paints
A12: Clearest SKU / Portfolio | B12: =COUNTIF('🏭 Distributor_Wholesaler'!L4:L18,"Asian Paints") -> 5 | C12: =COUNTIF('🏭 Distributor_Wholesaler'!L4:L18,"Birla Opus") -> 3 | D12: =COUNTIF('🏭 Distributor_Wholesaler'!L4:L18,"Dulux Paints") -> 3 | E12: =COUNTIF('🏭 Distributor_Wholesaler'!L4:L18,"JSW Paints") -> 4 | F12: =B12+C12+D12+E12 -> 15 | G12: =IFERROR(ROUND(B12/MAX(B12:E12)*10,1),0) -> 10 | H12: =IFERROR(ROUND(C12/MAX(B12:E12)*10,1),0) -> 6 | I12: =IFERROR(ROUND(D12/MAX(B12:E12)*10,1),0) -> 6 | J12: =IFERROR(ROUND(E12/MAX(B12:E12)*10,1),0) -> 8 | K12: =IFERROR(INDEX({"Asian Paints","Birla Opus","Dulux Paints","JSW Paints"},MATCH(MAX(B12:E12),B12:E12,0)),"-") -> Asian Paints
A13: Customer Top Choice | B13: =COUNTIF('👤 Customer'!L4:L38,"Asian Paints") -> 12 | C13: =COUNTIF('👤 Customer'!L4:L38,"Birla Opus") -> 9 | D13: =COUNTIF('👤 Customer'!L4:L38,"Dulux Paints") -> 7 | E13: =COUNTIF('👤 Customer'!L4:L38,"JSW Paints") -> 7 | F13: =B13+C13+D13+E13 -> 35 | G13: =IFERROR(ROUND(B13/MAX(B13:E13)*10,1),0) -> 10 | H13: =IFERROR(ROUND(C13/MAX(B13:E13)*10,1),0) -> 7.5 | I13: =IFERROR(ROUND(D13/MAX(B13:E13)*10,1),0) -> 5.8 | J13: =IFERROR(ROUND(E13/MAX(B13:E13)*10,1),0) -> 5.8 | K13: =IFERROR(INDEX({"Asian Paints","Birla Opus","Dulux Paints","JSW Paints"},MATCH(MAX(B13:E13),B13:E13,0)),"-") -> Asian Paints
A14: TOTAL MENTIONS (All Dimensions) | B14: =SUM(B4:B13) -> 110 | C14: =SUM(C4:C13) -> 60 | D14: =SUM(D4:D13) -> 50 | E14: =SUM(E4:E13) -> 70

Sheet 🔢 Sentiment_Coding
A1: 🔢 SENTIMENT CODING SHEET — Score each respondent 1–10 per dimension after interview
A2: CODEBOOK: Best in Market=10 | Excellent=9 | Very Good=8 | Good=7 | Average=5 | Slightly Confusing=4 | Confusing=3 | Poor=2 | Very Poor=1
A3: Resp. ID | B3: Respondent Name | C3: Stakeholder Type | D3: Shelf Visibility | E3: Premium Perception | F3: Product Clarity | G3: SKU Clarity | H3: Dealer Ease | I3: Trust Signal | J3: Modernity | K3: Overall Score | L3: Weighted Avg (/10)
A4: D001 | B4: Ravi Bose | C4: Dealer | D4: 10 | E4: 10 | F4: 8.5 | G4: 10 | H4: 9.4 | I4: 9.8 | J4: 9.6 | K4: 10 | L4: =IFERROR(AVERAGE(D4:K4),"") -> 9.6625
A5: D002 | B5: Sanjay Shah | C5: Dealer | D5: 5.9 | E5: 6.4 | F5: 5.7 | G5: 6.4 | H5: 4.8 | I5: 6.2 | J5: 7.6 | K5: 7.4 | L5: =IFERROR(AVERAGE(D5:K5),"") -> 6.3
A6: D003 | B6: Ganesh Gupta | C6: Dealer | D6: 9.3 | E6: 6.7 | F6: 10 | G6: 9.4 | H6: 9.2 | I6: 8.7 | J6: 8.1 | K6: 9.3 | L6: =IFERROR(AVERAGE(D6:K6),"") -> 8.8375
A7: D004 | B7: Ramesh Bose | C7: Dealer | D7: 7.8 | E7: 8.7 | F7: 8.4 | G7: 8.5 | H7: 8.6 | I7: 10 | J7: 9.1 | K7: 10 | L7: =IFERROR(AVERAGE(D7:K7),"") -> 8.8875
A8: D005 | B8: Kavita Dubey | C8: Dealer | D8: 6.4 | E8: 6.9 | F8: 4.8 | G8: 6.7 | H8: 5.1 | I8: 7 | J8: 7 | K8: 6.6 | L8: =IFERROR(AVERAGE(D8:K8),"") -> 6.3125
A9: D006 | B9: Bharat Sinha | C9: Dealer | D9: 6.6 | E9: 9.4 | F9: 7.3 | G9: 6.4 | H9: 8 | I9: 6.6 | J9: 8.7 | K9: 7.8 | L9: =IFERROR(AVERAGE(D9:K9),"") -> 7.6
A10: D007 | B10: Vinod Pillai | C10: Dealer | D10: 9 | E10: 9.5 | F10: 10 | G10: 8.7 | H10: 10 | I10: 10 | J10: 9.7 | K10: 9.7 | L10: =IFERROR(AVERAGE(D10:K10),"") -> 9.575
A11: D008 | B11: Kavita Tiwari | C11: Dealer | D11: 9.4 | E11: 7.1 | F11: 10 | G11: 8.6 | H11: 6 | I11: 10 | J11: 6.7 | K11: 10 | L11: =IFERROR(AVERAGE(D11:K11),"") -> 8.475
A12: D009 | B12: Rahul Yadav | C12: Dealer | D12: 10 | E12: 8.5 | F12: 8.3 | G12: 7.2 | H12: 7.6 | I12: 8.8 | J12: 8.1 | K12: 10 | L12: =IFERROR(AVERAGE(D12:K12),"") -> 8.5625
A13: D010 | B13: Bharat Das | C13: Dealer | D13: 5.5 | E13: 6.9 | F13: 6.9 | G13: 6 | H13: 6.8 | I13: 6.6 | J13: 6.9 | K13: 8.2 | L13: =IFERROR(AVERAGE(D13:K13),"") -> 6.725
A14: D011 | B14: Amit Rao | C14: Dealer | D14: 7.8 | E14: 8.7 | F14: 9.4 | G14: 8 | H14: 8.8 | I14: 10 | J14: 10 | K14: 8.8 | L14: =IFERROR(AVERAGE(D14:K14),"") -> 8.9375
A15: D012 | B15: Kavita Malhotra | C15: Dealer | D15: 9.7 | E15: 10 | F15: 6.4 | G15: 9 | H15: 8 | I15: 8.2 | J15: 8.6 | K15: 8.3 | L15: =IFERROR(AVERAGE(D15:K15),"") -> 8.525
